Workbook

Sheet 1月
A1: 2022年1月超声工作量
A2: 姓名 | B2: 体检例数 | C2: 腔内超声检查 | D2: 图文报告 | E2: 超声检查正常(包括双胎) | F2: 双胎加收 | G2: 脏器灰阶立体成象*2 | H2: 超声检查(胎儿系统) *3 | I2: 胎儿心脏超声 *3 | J2: 残余尿测定 | K2: 床旁彩超 *6 | L2: 床旁彩超加收 *5 | M2: B超常规检 | N2: 脏器声学造影 *5 | O2: 临床操作超声引导*5 | P2: 弹性成像 | Q2: 误时工作量例数 | R2: 疑难病例会诊例数 | S2: 夜班例数 | T2: 扣罚金额 | U2: 门住工作量合计 | V2: 门住体工作量合计 | W2: 绩效工作量 | X2: 门住收入合计 | Y2: 门住体总收入合计
B3: 99 | C3: 132 | D3: 5.5 | E3: 99 | F3: 55 | G3: 264 | H3: 310 | I3: 286 | J3: 55 | K3: 132 | L3: 33 | M3: 27.5 | N3: 143 | O3: 143 | P3: 55 | R3: 20 | S3: 50 | T3: 50-500
A4: 信吉伟 | B4: 970 | C4: 32 | D4: 312 | E4: 255 | G4: 118 | H4: 22 | J4: 5 | N4: 4 | O4: 38 | U4: =SUM(C4:P4)-D4 -> 474 | V4: =SUM(B4:P4)-D4 -> 1444 | W4: =B4+C4+E4+F4+G4*2+H4*3+I4*3+J4+K4*6+L4*5+M4+N4*5+O4*5+P4+Q4 -> 1774 | X4: =C4*$C$3+D4*$D$3+E4*$E$3+F4*$F$3+G4*$G$3+H4*$H$3+I4*$I$3+J4*$J$3+K4*$K$3+L4*$L$3+M4*$M$3+N4*$N$3+O4*$O$3+P4*$P$3 -> 75438 | Y4: =B4*99+C4*$C$3+D4*$D$3+E4*$E$3+F4*$F$3+G4*$G$3+H4*$H$3+I4*$I$3+J4*$J$3+K4*$K$3+L4*$L$3+M4*$M$3+N4*$N$3+O4*$O$3+P4*$P$3 -> 171468
A5: 刘思阳 | B5: 335 | D5: 424 | E5: 412 | G5: 81 | J5: 18 | U5: =SUM(C5:P5)-D5 -> 511 | V5: =SUM(B5:P5)-D5 -> 846 | W5: =B5+C5+E5+F5+G5*2+H5*3+I5*3+J5+K5*6+L5*5+M5+N5*5+O5*5+P5+Q5 -> 927 | X5: =C5*$C$3+D5*$D$3+E5*$E$3+F5*$F$3+G5*$G$3+H5*$H$3+I5*$I$3+J5*$J$3+K5*$K$3+L5*$L$3+M5*$M$3+N5*$N$3+O5*$O$3+P5*$P$3 -> 65494 | Y5: =B5*99+C5*$C$3+D5*$D$3+E5*$E$3+F5*$F$3+G5*$G$3+H5*$H$3+I5*$I$3+J5*$J$3+K5*$K$3+L5*$L$3+M5*$M$3+N5*$N$3+O5*$O$3+P5*$P$3 -> 98659
A6: 邢卫军 | B6: 375 | C6: 83 | D6: 471 | E6: 345 | G6: 125 | J6: 5 | K6: 8 | U6: =SUM(C6:P6)-D6 -> 566 | V6: =SUM(B6:P6)-D6 -> 941 | W6: =B6+C6+E6+F6+G6*2+H6*3+I6*3+J6+K6*6+L6*5+M6+N6*5+O6*5+P6+Q6 -> 1106 | X6: =C6*$C$3+D6*$D$3+E6*$E$3+F6*$F$3+G6*$G$3+H6*$H$3+I6*$I$3+J6*$J$3+K6*$K$3+L6*$L$3+M6*$M$3+N6*$N$3+O6*$O$3+P6*$P$3 -> 82032.5 | Y6: =B6*99+C6*$C$3+D6*$D$3+E6*$E$3+F6*$F$3+G6*$G$3+H6*$H$3+I6*$I$3+J6*$J$3+K6*$K$3+L6*$L$3+M6*$M$3+N6*$N$3+O6*$O$3+P6*$P$3 -> 119157.5
A7: 姜纯莲 | B7: 469 | C7: 117 | D7: 803 | E7: 496 | G7: 186 | J7: 8 | U7: =SUM(C7:P7)-D7 -> 807 | V7: =SUM(B7:P7)-D7 -> 1276 | W7: =B7+C7+E7+F7+G7*2+H7*3+I7*3+J7+K7*6+L7*5+M7+N7*5+O7*5+P7+Q7 -> 1462 | X7: =C7*$C$3+D7*$D$3+E7*$E$3+F7*$F$3+G7*$G$3+H7*$H$3+I7*$I$3+J7*$J$3+K7*$K$3+L7*$L$3+M7*$M$3+N7*$N$3+O7*$O$3+P7*$P$3 -> 118508.5 | Y7: =B7*99+C7*$C$3+D7*$D$3+E7*$E$3+F7*$F$3+G7*$G$3+H7*$H$3+I7*$I$3+J7*$J$3+K7*$K$3+L7*$L$3+M7*$M$3+N7*$N$3+O7*$O$3+P7*$P$3 -> 164939.5
A8: 王漠璇 | B8: 695 | C8: 76 | D8: 621 | E8: 473 | G8: 155 | J8: 8 | K8: 11 | L8: 1 | U8: =SUM(C8:P8)-D8 -> 724 | V8: =SUM(B8:P8)-D8 -> 1419 | W8: =B8+C8+E8+F8+G8*2+H8*3+I8*3+J8+K8*6+L8*5+M8+N8*5+O8*5+P8+Q8 -> 1633 | X8: =C8*$C$3+D8*$D$3+E8*$E$3+F8*$F$3+G8*$G$3+H8*$H$3+I8*$I$3+J8*$J$3+K8*$K$3+L8*$L$3+M8*$M$3+N8*$N$3+O8*$O$3+P8*$P$3 -> 103119.5 | Y8: =B8*99+C8*$C$3+D8*$D$3+E8*$E$3+F8*$F$3+G8*$G$3+H8*$H$3+I8*$I$3+J8*$J$3+K8*$K$3+L8*$L$3+M8*$M$3+N8*$N$3+O8*$O$3+P8*$P$3 -> 171924.5
A9: 汪亚新 | B9: 125 | C9: 0 | D9: 286 | E9: 268 | G9: 33 | J9: 6 | U9: =SUM(C9:P9)-D9 -> 307 | V9: =SUM(B9:P9)-D9 -> 432 | W9: =B9+C9+E9+F9+G9*2+H9*3+I9*3+J9+K9*6+L9*5+M9+N9*5+O9*5+P9+Q9 -> 465 | X9: =C9*$C$3+D9*$D$3+E9*$E$3+F9*$F$3+G9*$G$3+H9*$H$3+I9*$I$3+J9*$J$3+K9*$K$3+L9*$L$3+M9*$M$3+N9*$N$3+O9*$O$3+P9*$P$3 -> 37147 | Y9: =B9*99+C9*$C$3+D9*$D$3+E9*$E$3+F9*$F$3+G9*$G$3+H9*$H$3+I9*$I$3+J9*$J$3+K9*$K$3+L9*$L$3+M9*$M$3+N9*$N$3+O9*$O$3+P9*$P$3 -> 49522
A10: 李双生 | B10: 451 | C10: 2 | D10: 534 | E10: 518 | G10: 81 | J10: 15 | K10: 26 | U10: =SUM(C10:P10)-D10 -> 642 | V10: =SUM(B10:P10)-D10 -> 1093 | W10: =B10+C10+E10+F10+G10*2+H10*3+I10*3+J10+K10*6+L10*5+M10+N10*5+O10*5+P10+Q10 -> 1304 | X10: =C10*$C$3+D10*$D$3+E10*$E$3+F10*$F$3+G10*$G$3+H10*$H$3+I10*$I$3+J10*$J$3+K10*$K$3+L10*$L$3+M10*$M$3+N10*$N$3+O10*$O$3+P10*$P$3 -> 80124 | Y10: =B10*99+C10*$C$3+D10*$D$3+E10*$E$3+F10*$F$3+G10*$G$3+H10*$H$3+I10*$I$3+J10*$J$3+K10*$K$3+L10*$L$3+M10*$M$3+N10*$N$3+O10*$O$3+P10*$P$3 -> 124773
A11: 董宝玲 | B11: 297 | C11: 47 | D11: 472 | E11: 372 | G11: 130 | J11: 6 | K11: 3 | L11: 1 | U11: =SUM(C11:P11)-D11 -> 559 | V11: =SUM(B11:P11)-D11 -> 856 | W11: =B11+C11+E11+F11+G11*2+H11*3+I11*3+J11+K11*6+L11*5+M11+N11*5+O11*5+P11+Q11 -> 1005 | X11: =C11*$C$3+D11*$D$3+E11*$E$3+F11*$F$3+G11*$G$3+H11*$H$3+I11*$I$3+J11*$J$3+K11*$K$3+L11*$L$3+M11*$M$3+N11*$N$3+O11*$O$3+P11*$P$3 -> 80707 | Y11: =B11*99+C11*$C$3+D11*$D$3+E11*$E$3+F11*$F$3+G11*$G$3+H11*$H$3+I11*$I$3+J11*$J$3+K11*$K$3+L11*$L$3+M11*$M$3+N11*$N$3+O11*$O$3+P11*$P$3 -> 110110
A12: 周晓丽 | B12: 298 | C12: 36 | D12: 337 | E12: 303 | G12: 71 | H12: 2 | J12: 5 | L12: 19 | U12: =SUM(C12:P12)-D12 -> 436 | V12: =SUM(B12:P12)-D12 -> 734 | W12: =B12+C12+E12+F12+G12*2+H12*3+I12*3+J12+K12*6+L12*5+M12+N12*5+O12*5+P12+Q12 -> 885 | X12: =C12*$C$3+D12*$D$3+E12*$E$3+F12*$F$3+G12*$G$3+H12*$H$3+I12*$I$3+J12*$J$3+K12*$K$3+L12*$L$3+M12*$M$3+N12*$N$3+O12*$O$3+P12*$P$3 -> 56868.5 | Y12: =B12*99+C12*$C$3+D12*$D$3+E12*$E$3+F12*$F$3+G12*$G$3+H12*$H$3+I12*$I$3+J12*$J$3+K12*$K$3+L12*$L$3+M12*$M$3+N12*$N$3+O12*$O$3+P12*$P$3 -> 86370.5
A13: 刘炜 | B13: 679 | C13: 73 | D13: 531 | E13: 360 | G13: 152 | H13: 13 | I13: 6 | J13: 8 | K13: 7 | N13: 4 | U13: =SUM(C13:P13)-D13 -> 623 | V13: =SUM(B13:P13)-D13 -> 1302 | W13: =B13+C13+E13+F13+G13*2+H13*3+I13*3+J13+K13*6+L13*5+M13+N13*5+O13*5+P13+Q13 -> 1543 | X13: =C13*$C$3+D13*$D$3+E13*$E$3+F13*$F$3+G13*$G$3+H13*$H$3+I13*$I$3+J13*$J$3+K13*$K$3+L13*$L$3+M13*$M$3+N13*$N$3+O13*$O$3+P13*$P$3 -> 96006.5 | Y13: =B13*99+C13*$C$3+D13*$D$3+E13*$E$3+F13*$F$3+G13*$G$3+H13*$H$3+I13*$I$3+J13*$J$3+K13*$K$3+L13*$L$3+M13*$M$3+N13*$N$3+O13*$O$3+P13*$P$3 -> 163227.5
A14: 刘涛 | U14: =SUM(C14:P14)-D14 -> 0 | V14: =SUM(B14:P14)-D14 -> 0 | W14: =B14+C14+E14+F14+G14*2+H14*3+I14*3+J14+K14*6+L14*5+M14+N14*5+O14*5+P14+Q14 -> 0 | X14: =C14*$C$3+D14*$D$3+E14*$E$3+F14*$F$3+G14*$G$3+H14*$H$3+I14*$I$3+J14*$J$3+K14*$K$3+L14*$L$3+M14*$M$3+N14*$N$3+O14*$O$3+P14*$P$3 -> 0 | Y14: =B14*99+C14*$C$3+D14*$D$3+E14*$E$3+F14*$F$3+G14*$G$3+H14*$H$3+I14*$I$3+J14*$J$3+K14*$K$3+L14*$L$3+M14*$M$3+N14*$N$3+O14*$O$3+P14*$P$3 -> 0
A15: 朱凯 | B15: 614 | C15: 5 | D15: 391 | E15: 390 | G15: 55 | J15: 4 | K15: 12 | L15: 1 | U15: =SUM(C15:P15)-D15 -> 467 | V15: =SUM(B15:P15)-D15 -> 1081 | W15: =B15+C15+E15+F15+G15*2+H15*3+I15*3+J15+K15*6+L15*5+M15+N15*5+O15*5+P15+Q15 -> 1200 | X15: =C15*$C$3+D15*$D$3+E15*$E$3+F15*$F$3+G15*$G$3+H15*$H$3+I15*$I$3+J15*$J$3+K15*$K$3+L15*$L$3+M15*$M$3+N15*$N$3+O15*$O$3+P15*$P$3 -> 57777.5 | Y15: =B15*99+C15*$C$3+D15*$D$3+E15*$E$3+F15*$F$3+G15*$G$3+H15*$H$3+I15*$I$3+J15*$J$3+K15*$K$3+L15*$L$3+M15*$M$3+N15*$N$3+O15*$O$3+P15*$P$3 -> 118563.5
A16: 李晓莹 | B16: 675 | C16: 78 | D16: 630 | E16: 515 | G16: 157 | H16: 1 | J16: 9 | K16: 22 | L16: 7 | U16: =SUM(C16:P16)-D16 -> 789 | V16: =SUM(B16:P16)-D16 -> 1464 | W16: =B16+C16+E16+F16+G16*2+H16*3+I16*3+J16+K16*6+L16*5+M16+N16*5+O16*5+P16+Q16 -> 1761 | X16: =C16*$C$3+D16*$D$3+E16*$E$3+F16*$F$3+G16*$G$3+H16*$H$3+I16*$I$3+J16*$J$3+K16*$K$3+L16*$L$3+M16*$M$3+N16*$N$3+O16*$O$3+P16*$P$3 -> 110134 | Y16: =B16*99+C16*$C$3+D16*$D$3+E16*$E$3+F16*$F$3+G16*$G$3+H16*$H$3+I16*$I$3+J16*$J$3+K16*$K$3+L16*$L$3+M16*$M$3+N16*$N$3+O16*$O$3+P16*$P$3 -> 176959
A17: 孟凡伟 | B17: 248 | C17: 11 | D17: 638 | E17: 587 | G17: 65 | J17: 12 | K17: 3 | L17: 1 | U17: =SUM(C17:P17)-D17 -> 679 | V17: =SUM(B17:P17)-D17 -> 927 | W17: =B17+C17+E17+F17+G17*2+H17*3+I17*3+J17+K17*6+L17*5+M17+N17*5+O17*5+P17+Q17 -> 1011 | X17: =C17*$C$3+D17*$D$3+E17*$E$3+F17*$F$3+G17*$G$3+H17*$H$3+I17*$I$3+J17*$J$3+K17*$K$3+L17*$L$3+M17*$M$3+N17*$N$3+O17*$O$3+P17*$P$3 -> 81323 | Y17: =B17*99+C17*$C$3+D17*$D$3+E17*$E$3+F17*$F$3+G17*$G$3+H17*$H$3+I17*$I$3+J17*$J$3+K17*$K$3+L17*$L$3+M17*$M$3+N17*$N$3+O17*$O$3+P17*$P$3 -> 105875
A18: 王桐 | B18: 388 | C18: 37 | D18: 276 | E18: 201 | G18: 75 | J18: 1 | L18: 10 | U18: =SUM(C18:P18)-D18 -> 324 | V18: =SUM(B18:P18)-D18 -> 712 | W18: =B18+C18+E18+F18+G18*2+H18*3+I18*3+J18+K18*6+L18*5+M18+N18*5+O18*5+P18+Q18 -> 827 | X18: =C18*$C$3+D18*$D$3+E18*$E$3+F18*$F$3+G18*$G$3+H18*$H$3+I18*$I$3+J18*$J$3+K18*$K$3+L18*$L$3+M18*$M$3+N18*$N$3+O18*$O$3+P18*$P$3 -> 46486 | Y18: =B18*99+C18*$C$3+D18*$D$3+E18*$E$3+F18*$F$3+G18*$G$3+H18*$H$3+I18*$I$3+J18*$J$3+K18*$K$3+L18*$L$3+M18*$M$3+N18*$N$3+O18*$O$3+P18*$P$3 -> 84898
A19: 程日 | B19: 380 | C19: 7 | D19: 544 | E19: 576 | G19: 56 | J19: 8 | K19: 19 | U19: =SUM(C19:P19)-D19 -> 666 | V19: =SUM(B19:P19)-D19 -> 1046 | W19: =B19+C19+E19+F19+G19*2+H19*3+I19*3+J19+K19*6+L19*5+M19+N19*5+O19*5+P19+Q19 -> 1197 | X19: =C19*$C$3+D19*$D$3+E19*$E$3+F19*$F$3+G19*$G$3+H19*$H$3+I19*$I$3+J19*$J$3+K19*$K$3+L19*$L$3+M19*$M$3+N19*$N$3+O19*$O$3+P19*$P$3 -> 78672 | Y19: =B19*99+C19*$C$3+D19*$D$3+E19*$E$3+F19*$F$3+G19*$G$3+H19*$H$3+I19*$I$3+J19*$J$3+K19*$K$3+L19*$L$3+M19*$M$3+N19*$N$3+O19*$O$3+P19*$P$3 -> 116292
A20: 洪森 | B20: 93 | C20: 15 | D20: 439 | E20: 436 | G20: 54 | J20: 10 | K20: 15 | L20: 14 | U20: =SUM(C20:P20)-D20 -> 544 | V20: =SUM(B20:P20)-D20 -> 637 | W20: =B20+C20+E20+F20+G20*2+H20*3+I20*3+J20+K20*6+L20*5+M20+N20*5+O20*5+P20+Q20 -> 822 | X20: =C20*$C$3+D20*$D$3+E20*$E$3+F20*$F$3+G20*$G$3+H20*$H$3+I20*$I$3+J20*$J$3+K20*$K$3+L20*$L$3+M20*$M$3+N20*$N$3+O20*$O$3+P20*$P$3 -> 64806.5 | Y20: =B20*99+C20*$C$3+D20*$D$3+E20*$E$3+F20*$F$3+G20*$G$3+H20*$H$3+I20*$I$3+J20*$J$3+K20*$K$3+L20*$L$3+M20*$M$3+N20*$N$3+O20*$O$3+P20*$P$3 -> 74013.5
A21: 马延梁 | B21: 996 | C21: 13 | D21: 412 | E21: 418 | G21: 41 | J21: 8 | K21: 31 | L21: 5 | U21: =SUM(C21:P21)-D21 -> 516 | V21: =SUM(B21:P21)-D21 -> 1512 | W21: =B21+C21+E21+F21+G21*2+H21*3+I21*3+J21+K21*6+L21*5+M21+N21*5+O21*5+P21+Q21 -> 1728 | X21: =C21*$C$3+D21*$D$3+E21*$E$3+F21*$F$3+G21*$G$3+H21*$H$3+I21*$I$3+J21*$J$3+K21*$K$3+L21*$L$3+M21*$M$3+N21*$N$3+O21*$O$3+P21*$P$3 -> 60885 | Y21: =B21*99+C21*$C$3+D21*$D$3+E21*$E$3+F21*$F$3+G21*$G$3+H21*$H$3+I21*$I$3+J21*$J$3+K21*$K$3+L21*$L$3+M21*$M$3+N21*$N$3+O21*$O$3+P21*$P$3 -> 159489
A22: 史嘉琳 | B22: 391 | C22: 123 | D22: 739 | E22: 541 | G22: 188 | J22: 4 | M22: 1 | U22: =SUM(C22:P22)-D22 -> 857 | V22: =SUM(B22:P22)-D22 -> 1248 | W22: =B22+C22+E22+F22+G22*2+H22*3+I22*3+J22+K22*6+L22*5+M22+N22*5+O22*5+P22+Q22 -> 1436 | X22: =C22*$C$3+D22*$D$3+E22*$E$3+F22*$F$3+G22*$G$3+H22*$H$3+I22*$I$3+J22*$J$3+K22*$K$3+L22*$L$3+M22*$M$3+N22*$N$3+O22*$O$3+P22*$P$3 -> 123739 | Y22: =B22*99+C22*$C$3+D22*$D$3+E22*$E$3+F22*$F$3+G22*$G$3+H22*$H$3+I22*$I$3+J22*$J$3+K22*$K$3+L22*$L$3+M22*$M$3+N22*$N$3+O22*$O$3+P22*$P$3 -> 162448
A23: 孙承飞 | B23: 398 | C23: 4 | D23: 293 | E23: 340 | G23: 18 | J23: 7 | K23: 21 | L23: 4 | U23: =SUM(C23:P23)-D23 -> 394 | V23: =SUM(B23:P23)-D23 -> 792 | W23: =B23+C23+E23+F23+G23*2+H23*3+I23*3+J23+K23*6+L23*5+M23+N23*5+O23*5+P23+Q23 -> 931 | X23: =C23*$C$3+D23*$D$3+E23*$E$3+F23*$F$3+G23*$G$3+H23*$H$3+I23*$I$3+J23*$J$3+K23*$K$3+L23*$L$3+M23*$M$3+N23*$N$3+O23*$O$3+P23*$P$3 -> 43840.5 | Y23: =B23*99+C23*$C$3+D23*$D$3+E23*$E$3+F23*$F$3+G23*$G$3+H23*$H$3+I23*$I$3+J23*$J$3+K23*$K$3+L23*$L$3+M23*$M$3+N23*$N$3+O23*$O$3+P23*$P$3 -> 83242.5
A24: 赵希平 | B24: 234 | C24: 10 | D24: 635 | E24: 634 | G24: 76 | J24: 14 | K24: 13 | M24: 1 | U24: =SUM(C24:P24)-D24 -> 748 | V24: =SUM(B24:P24)-D24 -> 982 | W24: =B24+C24+E24+F24+G24*2+H24*3+I24*3+J24+K24*6+L24*5+M24+N24*5+O24*5+P24+Q24 -> 1123 | X24: =C24*$C$3+D24*$D$3+E24*$E$3+F24*$F$3+G24*$G$3+H24*$H$3+I24*$I$3+J24*$J$3+K24*$K$3+L24*$L$3+M24*$M$3+N24*$N$3+O24*$O$3+P24*$P$3 -> 90156 | Y24: =B24*99+C24*$C$3+D24*$D$3+E24*$E$3+F24*$F$3+G24*$G$3+H24*$H$3+I24*$I$3+J24*$J$3+K24*$K$3+L24*$L$3+M24*$M$3+N24*$N$3+O24*$O$3+P24*$P$3 -> 113322
A25: 李楠 | U25: =SUM(C25:P25)-D25 -> 0 | V25: =SUM(B25:P25)-D25 -> 0 | W25: =B25+C25+E25+F25+G25*2+H25*3+I25*3+J25+K25*6+L25*5+M25+N25*5+O25*5+P25+Q25 -> 0 | X25: =C25*$C$3+D25*$D$3+E25*$E$3+F25*$F$3+G25*$G$3+H25*$H$3+I25*$I$3+J25*$J$3+K25*$K$3+L25*$L$3+M25*$M$3+N25*$N$3+O25*$O$3+P25*$P$3 -> 0 | Y25: =B25*99+C25*$C$3+D25*$D$3+E25*$E$3+F25*$F$3+G25*$G$3+H25*$H$3+I25*$I$3+J25*$J$3+K25*$K$3+L25*$L$3+M25*$M$3+N25*$N$3+O25*$O$3+P25*$P$3 -> 0
A26: 李嘉鹏 | B26: 8 | D26: 10 | E26: 8 | J26: 1 | K26: 2 | U26: =SUM(C26:P26)-D26 -> 11 | V26: =SUM(B26:P26)-D26 -> 19 | W26: =B26+C26+E26+F26+G26*2+H26*3+I26*3+J26+K26*6+L26*5+M26+N26*5+O26*5+P26+Q26 -> 29 | X26: =C26*$C$3+D26*$D$3+E26*$E$3+F26*$F$3+G26*$G$3+H26*$H$3+I26*$I$3+J26*$J$3+K26*$K$3+L26*$L$3+M26*$M$3+N26*$N$3+O26*$O$3+P26*$P$3 -> 1166 | Y26: =B26*99+C26*$C$3+D26*$D$3+E26*$E$3+F26*$F$3+G26*$G$3+H26*$H$3+I26*$I$3+J26*$J$3+K26*$K$3+L26*$L$3+M26*$M$3+N26*$N$3+O26*$O$3+P26*$P$3 -> 1958
U27: =SUM(C27:P27)-D27 -> 0 | V27: =SUM(B27:P27)-D27 -> 0 | W27: =B27+C27+E27+F27+G27*2+H27*3+I27*3+J27+K27*6+L27*5+M27+N27*5+O27*5+P27+Q27 -> 0 | X27: =C27*$C$3+D27*$D$3+E27*$E$3+F27*$F$3+G27*$G$3+H27*$H$3+I27*$I$3+J27*$J$3+K27*$K$3+L27*$L$3+M27*$M$3+N27*$N$3+O27*$O$3+P27*$P$3 -> 0 | Y27: =B27*99+C27*$C$3+D27*$D$3+E27*$E$3+F27*$F$3+G27*$G$3+H27*$H$3+I27*$I$3+J27*$J$3+K27*$K$3+L27*$L$3+M27*$M$3+N27*$N$3+O27*$O$3+P27*$P$3 -> 0
A28: 韩天福 | D28: 24 | E28: 27 | G28: 4 | L28: 7 | U28: =SUM(C28:P28)-D28 -> 38 | V28: =SUM(B28:P28)-D28 -> 38 | W28: =B28+C28+E28+F28+G28*2+H28*3+I28*3+J28+K28*6+L28*5+M28+N28*5+O28*5+P28+Q28 -> 70 | X28: =C28*$C$3+D28*$D$3+E28*$E$3+F28*$F$3+G28*$G$3+H28*$H$3+I28*$I$3+J28*$J$3+K28*$K$3+L28*$L$3+M28*$M$3+N28*$N$3+O28*$O$3+P28*$P$3 -> 4092 | Y28: =B28*99+C28*$C$3+D28*$D$3+E28*$E$3+F28*$F$3+G28*$G$3+H28*$H$3+I28*$I$3+J28*$J$3+K28*$K$3+L28*$L$3+M28*$M$3+N28*$N$3+O28*$O$3+P28*$P$3 -> 4092
A29: 刘海燕 | B29: 806 | C29: 21 | D29: 259 | E29: 225 | G29: 54 | J29: 3 | U29: =SUM(C29:P29)-D29 -> 303 | V29: =SUM(B29:P29)-D29 -> 1109 | W29: 0 | X29: =C29*$C$3+D29*$D$3+E29*$E$3+F29*$F$3+G29*$G$3+H29*$H$3+I29*$I$3+J29*$J$3+K29*$K$3+L29*$L$3+M29*$M$3+N29*$N$3+O29*$O$3+P29*$P$3 -> 40892.5 | Y29: =B29*99+C29*$C$3+D29*$D$3+E29*$E$3+F29*$F$3+G29*$G$3+H29*$H$3+I29*$I$3+J29*$J$3+K29*$K$3+L29*$L$3+M29*$M$3+N29*$N$3+O29*$O$3+P29*$P$3 -> 120686.5
U30: =SUM(B30:Q30) -> 0 | V30: =SUM(B30:P30)-D30 -> 0 | W30: =B30+C30+E30+F30+G30*2+H30*3+I30*3+J30+K30*6+L30*5+M30+N30*5+O30*5+P30+Q30 -> 0 | X30: =C30*$C$3+D30*$D$3+E30*$E$3+F30*$F$3+G30*$G$3+H30*$H$3+I30*$I$3+J30*$J$3+K30*$K$3+L30*$L$3+M30*$M$3+N30*$N$3+O30*$O$3+P30*$P$3 -> 0 | Y30: =B30*99+C30*$C$3+D30*$D$3+E30*$E$3+F30*$F$3+G30*$G$3+H30*$H$3+I30*$I$3+J30*$J$3+K30*$K$3+L30*$L$3+M30*$M$3+N30*$N$3+O30*$O$3+P30*$P$3 -> 0
A31: 工作量合计 | B31: =SUM(B4:B30) -> 9925 | C31: =SUM(C4:C30) -> 790 | D31: =SUM(D4:D30) -> 10081 | E31: =SUM(E4:E30) -> 8700 | F31: =SUM(F4:F30) -> 0 | G31: =SUM(G4:G30) -> 1975 | H31: =SUM(H4:H30) -> 38 | I31: =SUM(I4:I30) -> 6 | ... U31: =SUM(U4:U30) -> 11985 | V31: =SUM(B31:P31)-D31 -> 21910 | W31: =SUM(W4:W30) -> 24239 | X31: =SUM(X4:X30) -> 1599415.5 | Y31: =B31*99+C31*$C$3+D31*$D$3+E31*$E$3+F31*$F$3+G31*$G$3+H31*$H$3+I31*$I$3+J31*$J$3+K31*$K$3+L31*$L$3+M31*$M$3+N31*$N$3+O31*$O$3+P31*$P$3 -> 2581990.5
A32: 收入合计 | B32: =B31*B3 -> 982575 | C32: =C31*C3 -> 104280 | D32: =D31*D3 -> 55445.5 | E32: =E31*E3 -> 861300 | F32: =F31*F3 -> 0 | G32: =G31*G3 -> 521400 | H32: =H31*H3 -> 11780 | I32: =I31*I3 -> 1716 | ... P32: =P31*P3 -> 0 | U32: - | V32: - | W32: - | X32: =SUM(C32:P32) -> 1599415.5 | Y32: =SUM(B32:P32) -> 2581990.5

Sheet 2月
A1: 2022年2月超声工作量
A2: 姓名 | B2: 体检例数 | C2: 腔内超声检查 | D2: 图文报告 | E2: 超声检查正常(包括双胎) | F2: 双胎加收 | G2: 脏器灰阶立体成象*2 | H2: 超声检查(胎儿系统) *3 | I2: 胎儿心脏超声 *3 | J2: 残余尿测定 | K2: 床旁彩超 *6 | L2: 床旁彩超加收 *5 | M2: B超常规检 | N2: 脏器声学造影 *5 | O2: 临床操作超声引导*5 | P2: 弹性成像 | Q2: 误时工作量例数 | R2: 疑难病例会诊例数 | S2: 夜班例数 | T2: 扣罚金额 | U2: 门住工作量合计 | V2: 门住体工作量合计 | W2: 绩效工作量 | X2: 门住收入合计 | Y2: 门住体总收入合计
B3: 99 | C3: 132 | D3: 5.5 | E3: 99 | F3: 55 | G3: 264 | H3: 310 | I3: 286 | J3: 55 | K3: 132 | L3: 33 | M3: 27.5 | N3: 143 | O3: 143 | P3: 55 | R3: 20 | S3: 50 | T3: 50-500
A4: 信吉伟 | B4: 30 | C4: 35 | D4: 476 | E4: 433 | G4: 142 | H4: 24 | I4: 4 | N4: 2 | O4: 19 | Q4: 80 | R4: 84 | U4: =SUM(C4:P4)-D4 -> 659 | V4: =SUM(B4:P4)-D4 -> 689 | W4: =B4+C4+E4+F4+G4*2+H4*3+I4*3+J4+K4*6+L4*5+M4+N4*5+O4*5+P4+Q4 -> 1051 | X4: =C4*$C$3+D4*$D$3+E4*$E$3+F4*$F$3+G4*$G$3+H4*$H$3+I4*$I$3+J4*$J$3+K4*$K$3+L4*$L$3+M4*$M$3+N4*$N$3+O4*$O$3+P4*$P$3 -> 99180 | Y4: =B4*99+C4*$C$3+D4*$D$3+E4*$E$3+F4*$F$3+G4*$G$3+H4*$H$3+I4*$I$3+J4*$J$3+K4*$K$3+L4*$L$3+M4*$M$3+N4*$N$3+O4*$O$3+P4*$P$3 -> 102150
A5: 刘思阳 | B5: 3 | D5: 434 | E5: 439 | G5: 84 | J5: 12 | O5: 1 | R5: 4 | U5: =SUM(C5:P5)-D5 -> 536 | V5: =SUM(B5:P5)-D5 -> 539 | W5: =B5+C5+E5+F5+G5*2+H5*3+I5*3+J5+K5*6+L5*5+M5+N5*5+O5*5+P5+Q5 -> 627 | X5: =C5*$C$3+D5*$D$3+E5*$E$3+F5*$F$3+G5*$G$3+H5*$H$3+I5*$I$3+J5*$J$3+K5*$K$3+L5*$L$3+M5*$M$3+N5*$N$3+O5*$O$3+P5*$P$3 -> 68827 | Y5: =B5*99+C5*$C$3+D5*$D$3+E5*$E$3+F5*$F$3+G5*$G$3+H5*$H$3+I5*$I$3+J5*$J$3+K5*$K$3+L5*$L$3+M5*$M$3+N5*$N$3+O5*$O$3+P5*$P$3 -> 69124
A6: 邢卫军 | B6: 220 | C6: 112 | D6: 526 | E6: 357 | G6: 125 | J6: 5 | R6: 4 | U6: =SUM(C6:P6)-D6 -> 599 | V6: =SUM(B6:P6)-D6 -> 819 | W6: =B6+C6+E6+F6+G6*2+H6*3+I6*3+J6+K6*6+L6*5+M6+N6*5+O6*5+P6+Q6 -> 944 | X6: =C6*$C$3+D6*$D$3+E6*$E$3+F6*$F$3+G6*$G$3+H6*$H$3+I6*$I$3+J6*$J$3+K6*$K$3+L6*$L$3+M6*$M$3+N6*$N$3+O6*$O$3+P6*$P$3 -> 86295 | Y6: =B6*99+C6*$C$3+D6*$D$3+E6*$E$3+F6*$F$3+G6*$G$3+H6*$H$3+I6*$I$3+J6*$J$3+K6*$K$3+L6*$L$3+M6*$M$3+N6*$N$3+O6*$O$3+P6*$P$3 -> 108075
A7: 姜纯莲 | B7: 306 | C7: 121 | D7: 644 | E7: 477 | G7: 164 | H7: 1 | J7: 2 | L7: 1 | R7: 2 | U7: =SUM(C7:P7)-D7 -> 766 | V7: =SUM(B7:P7)-D7 -> 1072 | W7: =B7+C7+E7+F7+G7*2+H7*3+I7*3+J7+K7*6+L7*5+M7+N7*5+O7*5+P7+Q7 -> 1242 | X7: =C7*$C$3+D7*$D$3+E7*$E$3+F7*$F$3+G7*$G$3+H7*$H$3+I7*$I$3+J7*$J$3+K7*$K$3+L7*$L$3+M7*$M$3+N7*$N$3+O7*$O$3+P7*$P$3 -> 110486 | Y7: =B7*99+C7*$C$3+D7*$D$3+E7*$E$3+F7*$F$3+G7*$G$3+H7*$H$3+I7*$I$3+J7*$J$3+K7*$K$3+L7*$L$3+M7*$M$3+N7*$N$3+O7*$O$3+P7*$P$3 -> 140780
A8: 王漠璇 | B8: 204 | C8: 176 | D8: 728 | E8: 489 | G8: 244 | J8: 8 | K8: 10 | L8: 4 | R8: 4 | S8: 4 | U8: =SUM(C8:P8)-D8 -> 931 | V8: =SUM(B8:P8)-D8 -> 1135 | W8: =B8+C8+E8+F8+G8*2+H8*3+I8*3+J8+K8*6+L8*5+M8+N8*5+O8*5+P8+Q8 -> 1445 | X8: =C8*$C$3+D8*$D$3+E8*$E$3+F8*$F$3+G8*$G$3+H8*$H$3+I8*$I$3+J8*$J$3+K8*$K$3+L8*$L$3+M8*$M$3+N8*$N$3+O8*$O$3+P8*$P$3 -> 141955 | Y8: =B8*99+C8*$C$3+D8*$D$3+E8*$E$3+F8*$F$3+G8*$G$3+H8*$H$3+I8*$I$3+J8*$J$3+K8*$K$3+L8*$L$3+M8*$M$3+N8*$N$3+O8*$O$3+P8*$P$3 -> 162151
A9: 汪亚新 | B9: 84 | C9: 1 | D9: 263 | E9: 231 | G9: 40 | J9: 4 | R9: 4 | U9: =SUM(C9:P9)-D9 -> 276 | V9: =SUM(B9:P9)-D9 -> 360 | W9: =B9+C9+E9+F9+G9*2+H9*3+I9*3+J9+K9*6+L9*5+M9+N9*5+O9*5+P9+Q9 -> 400 | X9: =C9*$C$3+D9*$D$3+E9*$E$3+F9*$F$3+G9*$G$3+H9*$H$3+I9*$I$3+J9*$J$3+K9*$K$3+L9*$L$3+M9*$M$3+N9*$N$3+O9*$O$3+P9*$P$3 -> 35227.5 | Y9: =B9*99+C9*$C$3+D9*$D$3+E9*$E$3+F9*$F$3+G9*$G$3+H9*$H$3+I9*$I$3+J9*$J$3+K9*$K$3+L9*$L$3+M9*$M$3+N9*$N$3+O9*$O$3+P9*$P$3 -> 43543.5
A10: 李双生 | B10: 265 | C10: 3 | D10: 413 | E10: 441 | G10: 47 | J10: 12 | K10: 26 | R10: 4 | S10: 3 | U10: =SUM(C10:P10)-D10 -> 529 | V10: =SUM(B10:P10)-D10 -> 794 | W10: =B10+C10+E10+F10+G10*2+H10*3+I10*3+J10+K10*6+L10*5+M10+N10*5+O10*5+P10+Q10 -> 971 | X10: =C10*$C$3+D10*$D$3+E10*$E$3+F10*$F$3+G10*$G$3+H10*$H$3+I10*$I$3+J10*$J$3+K10*$K$3+L10*$L$3+M10*$M$3+N10*$N$3+O10*$O$3+P10*$P$3 -> 62826.5 | Y10: =B10*99+C10*$C$3+D10*$D$3+E10*$E$3+F10*$F$3+G10*$G$3+H10*$H$3+I10*$I$3+J10*$J$3+K10*$K$3+L10*$L$3+M10*$M$3+N10*$N$3+O10*$O$3+P10*$P$3 -> 89061.5
A11: 董宝玲 | B11: 305 | C11: 77 | D11: 445 | E11: 313 | G11: 108 | J11: 3 | K11: 11 | L11: 4 | S11: 4 | U11: =SUM(C11:P11)-D11 -> 516 | V11: =SUM(B11:P11)-D11 -> 821 | W11: =B11+C11+E11+F11+G11*2+H11*3+I11*3+J11+K11*6+L11*5+M11+N11*5+O11*5+P11+Q11 -> 1000 | X11: =C11*$C$3+D11*$D$3+E11*$E$3+F11*$F$3+G11*$G$3+H11*$H$3+I11*$I$3+J11*$J$3+K11*$K$3+L11*$L$3+M11*$M$3+N11*$N$3+O11*$O$3+P11*$P$3 -> 73859.5 | Y11: =B11*99+C11*$C$3+D11*$D$3+E11*$E$3+F11*$F$3+G11*$G$3+H11*$H$3+I11*$I$3+J11*$J$3+K11*$K$3+L11*$L$3+M11*$M$3+N11*$N$3+O11*$O$3+P11*$P$3 -> 104054.5
A12: 周晓丽 | B12: 144 | C12: 30 | D12: 298 | E12: 246 | G12: 92 | J12: 2 | K12: 26 | R12: 4 | S12: 4 | U12: =SUM(C12:P12)-D12 -> 396 | V12: =SUM(B12:P12)-D12 -> 540 | W12: =B12+C12+E12+F12+G12*2+H12*3+I12*3+J12+K12*6+L12*5+M12+N12*5+O12*5+P12+Q12 -> 762 | X12: =C12*$C$3+D12*$D$3+E12*$E$3+F12*$F$3+G12*$G$3+H12*$H$3+I12*$I$3+J12*$J$3+K12*$K$3+L12*$L$3+M12*$M$3+N12*$N$3+O12*$O$3+P12*$P$3 -> 57783 | Y12: =B12*99+C12*$C$3+D12*$D$3+E12*$E$3+F12*$F$3+G12*$G$3+H12*$H$3+I12*$I$3+J12*$J$3+K12*$K$3+L12*$L$3+M12*$M$3+N12*$N$3+O12*$O$3+P12*$P$3 -> 72039
A13: 刘炜 | B13: 107 | C13: 74 | D13: 592 | E13: 430 | F13: 1 | G13: 158 | H13: 4 | I13: 5 | J13: 3 | K13: 26 | N13: 2 | R13: 4 | S13: 4 | U13: =SUM(C13:P13)-D13 -> 703 | V13: =SUM(B13:P13)-D13 -> 810 | W13: =B13+C13+E13+F13+G13*2+H13*3+I13*3+J13+K13*6+L13*5+M13+N13*5+O13*5+P13+Q13 -> 1124 | X13: =C13*$C$3+D13*$D$3+E13*$E$3+F13*$F$3+G13*$G$3+H13*$H$3+I13*$I$3+J13*$J$3+K13*$K$3+L13*$L$3+M13*$M$3+N13*$N$3+O13*$O$3+P13*$P$3 -> 103914 | Y13: =B13*99+C13*$C$3+D13*$D$3+E13*$E$3+F13*$F$3+G13*$G$3+H13*$H$3+I13*$I$3+J13*$J$3+K13*$K$3+L13*$L$3+M13*$M$3+N13*$N$3+O13*$O$3+P13*$P$3 -> 114507
A14: 刘涛 | U14: =SUM(C14:P14)-D14 -> 0 | V14: =SUM(B14:P14)-D14 -> 0 | W14: =B14+C14+E14+F14+G14*2+H14*3+I14*3+J14+K14*6+L14*5+M14+N14*5+O14*5+P14+Q14 -> 0 | X14: =C14*$C$3+D14*$D$3+E14*$E$3+F14*$F$3+G14*$G$3+H14*$H$3+I14*$I$3+J14*$J$3+K14*$K$3+L14*$L$3+M14*$M$3+N14*$N$3+O14*$O$3+P14*$P$3 -> 0 | Y14: =B14*99+C14*$C$3+D14*$D$3+E14*$E$3+F14*$F$3+G14*$G$3+H14*$H$3+I14*$I$3+J14*$J$3+K14*$K$3+L14*$L$3+M14*$M$3+N14*$N$3+O14*$O$3+P14*$P$3 -> 0
A15: 朱凯 | B15: 125 | C15: 8 | D15: 617 | E15: 628 | F15: 1 | G15: 84 | J15: 9 | K15: 9 | L15: 2 | O15: 7 | R15: 2 | S15: 4 | U15: =SUM(C15:P15)-D15 -> 748 | V15: =SUM(B15:P15)-D15 -> 873 | W15: =B15+C15+E15+F15+G15*2+H15*3+I15*3+J15+K15*6+L15*5+M15+N15*5+O15*5+P15+Q15 -> 1038 | X15: =C15*$C$3+D15*$D$3+E15*$E$3+F15*$F$3+G15*$G$3+H15*$H$3+I15*$I$3+J15*$J$3+K15*$K$3+L15*$L$3+M15*$M$3+N15*$N$3+O15*$O$3+P15*$P$3 -> 91602.5 | Y15: =B15*99+C15*$C$3+D15*$D$3+E15*$E$3+F15*$F$3+G15*$G$3+H15*$H$3+I15*$I$3+J15*$J$3+K15*$K$3+L15*$L$3+M15*$M$3+N15*$N$3+O15*$O$3+P15*$P$3 -> 103977.5
A16: 李晓莹 | B16: 419 | C16: 74 | D16: 591 | E16: 446 | G16: 166 | H16: 2 | J16: 3 | K16: 7 | L16: 3 | R16: 4 | S16: 4 | U16: =SUM(C16:P16)-D16 -> 701 | V16: =SUM(B16:P16)-D16 -> 1120 | W16: =B16+C16+E16+F16+G16*2+H16*3+I16*3+J16+K16*6+L16*5+M16+N16*5+O16*5+P16+Q16 -> 1337 | X16: =C16*$C$3+D16*$D$3+E16*$E$3+F16*$F$3+G16*$G$3+H16*$H$3+I16*$I$3+J16*$J$3+K16*$K$3+L16*$L$3+M16*$M$3+N16*$N$3+O16*$O$3+P16*$P$3 -> 102804.5 | Y16: =B16*99+C16*$C$3+D16*$D$3+E16*$E$3+F16*$F$3+G16*$G$3+H16*$H$3+I16*$I$3+J16*$J$3+K16*$K$3+L16*$L$3+M16*$M$3+N16*$N$3+O16*$O$3+P16*$P$3 -> 144285.5
A17: 孟凡伟 | B17: 236 | C17: 3 | D17: 589 | E17: 558 | G17: 117 | J17: 25 | K17: 18 | R17: 4 | S17: 4 | U17: =SUM(C17:P17)-D17 -> 721 | V17: =SUM(B17:P17)-D17 -> 957 | W17: =B17+C17+E17+F17+G17*2+H17*3+I17*3+J17+K17*6+L17*5+M17+N17*5+O17*5+P17+Q17 -> 1164 | X17: =C17*$C$3+D17*$D$3+E17*$E$3+F17*$F$3+G17*$G$3+H17*$H$3+I17*$I$3+J17*$J$3+K17*$K$3+L17*$L$3+M17*$M$3+N17*$N$3+O17*$O$3+P17*$P$3 -> 93516.5 | Y17: =B17*99+C17*$C$3+D17*$D$3+E17*$E$3+F17*$F$3+G17*$G$3+H17*$H$3+I17*$I$3+J17*$J$3+K17*$K$3+L17*$L$3+M17*$M$3+N17*$N$3+O17*$O$3+P17*$P$3 -> 116880.5
A18: 王桐 | B18: 317 | C18: 38 | D18: 305 | E18: 272 | G18: 91 | H18: 1 | J18: 1 | L18: 6 | R18: 4 | S18: 4 | U18: =SUM(C18:P18)-D18 -> 409 | V18: =SUM(B18:P18)-D18 -> 726 | W18: =B18+C18+E18+F18+G18*2+H18*3+I18*3+J18+K18*6+L18*5+M18+N18*5+O18*5+P18+Q18 -> 843 | X18: =C18*$C$3+D18*$D$3+E18*$E$3+F18*$F$3+G18*$G$3+H18*$H$3+I18*$I$3+J18*$J$3+K18*$K$3+L18*$L$3+M18*$M$3+N18*$N$3+O18*$O$3+P18*$P$3 -> 58208.5 | Y18: =B18*99+C18*$C$3+D18*$D$3+E18*$E$3+F18*$F$3+G18*$G$3+H18*$H$3+I18*$I$3+J18*$J$3+K18*$K$3+L18*$L$3+M18*$M$3+N18*$N$3+O18*$O$3+P18*$P$3 -> 89591.5
A19: 程日 | B19: 290 | C19: 11 | D19: 440 | E19: 453 | G19: 53 | J19: 7 | K19: 17 | R19: 4 | S19: 4 | U19: =SUM(C19:P19)-D19 -> 541 | V19: =SUM(B19:P19)-D19 -> 831 | W19: =B19+C19+E19+F19+G19*2+H19*3+I19*3+J19+K19*6+L19*5+M19+N19*5+O19*5+P19+Q19 -> 969 | X19: =C19*$C$3+D19*$D$3+E19*$E$3+F19*$F$3+G19*$G$3+H19*$H$3+I19*$I$3+J19*$J$3+K19*$K$3+L19*$L$3+M19*$M$3+N19*$N$3+O19*$O$3+P19*$P$3 -> 65340 | Y19: =B19*99+C19*$C$3+D19*$D$3+E19*$E$3+F19*$F$3+G19*$G$3+H19*$H$3+I19*$I$3+J19*$J$3+K19*$K$3+L19*$L$3+M19*$M$3+N19*$N$3+O19*$O$3+P19*$P$3 -> 94050
A20: 洪森 | B20: 253 | C20: 3 | D20: 589 | E20: 604 | G20: 77 | J20: 23 | K20: 12 | L20: 1 | O20: 1 | R20: 2 | S20: 4 | U20: =SUM(C20:P20)-D20 -> 721 | V20: =SUM(B20:P20)-D20 -> 974 | W20: =B20+C20+E20+F20+G20*2+H20*3+I20*3+J20+K20*6+L20*5+M20+N20*5+O20*5+P20+Q20 -> 1119 | X20: =C20*$C$3+D20*$D$3+E20*$E$3+F20*$F$3+G20*$G$3+H20*$H$3+I20*$I$3+J20*$J$3+K20*$K$3+L20*$L$3+M20*$M$3+N20*$N$3+O20*$O$3+P20*$P$3 -> 86784.5 | Y20: =B20*99+C20*$C$3+D20*$D$3+E20*$E$3+F20*$F$3+G20*$G$3+H20*$H$3+I20*$I$3+J20*$J$3+K20*$K$3+L20*$L$3+M20*$M$3+N20*$N$3+O20*$O$3+P20*$P$3 -> 111831.5
A21: 马延梁 | B21: 453 | C21: 14 | D21: 532 | E21: 588 | G21: 63 | J21: 29 | K21: 20 | L21: 4 | R21: 4 | S21: 8 | U21: =SUM(C21:P21)-D21 -> 718 | V21: =SUM(B21:P21)-D21 -> 1171 | W21: =B21+C21+E21+F21+G21*2+H21*3+I21*3+J21+K21*6+L21*5+M21+N21*5+O21*5+P21+Q21 -> 1350 | X21: =C21*$C$3+D21*$D$3+E21*$E$3+F21*$F$3+G21*$G$3+H21*$H$3+I21*$I$3+J21*$J$3+K21*$K$3+L21*$L$3+M21*$M$3+N21*$N$3+O21*$O$3+P21*$P$3 -> 83985 | Y21: =B21*99+C21*$C$3+D21*$D$3+E21*$E$3+F21*$F$3+G21*$G$3+H21*$H$3+I21*$I$3+J21*$J$3+K21*$K$3+L21*$L$3+M21*$M$3+N21*$N$3+O21*$O$3+P21*$P$3 -> 128832
A22: 史嘉琳 | B22: 117 | C22: 192 | D22: 928 | E22: 536 | F22: 1 | G22: 255 | J22: 5 | R22: 4 | S22: 1 | U22: =SUM(C22:P22)-D22 -> 989 | V22: =SUM(B22:P22)-D22 -> 1106 | W22: =B22+C22+E22+F22+G22*2+H22*3+I22*3+J22+K22*6+L22*5+M22+N22*5+O22*5+P22+Q22 -> 1361 | X22: =C22*$C$3+D22*$D$3+E22*$E$3+F22*$F$3+G22*$G$3+H22*$H$3+I22*$I$3+J22*$J$3+K22*$K$3+L22*$L$3+M22*$M$3+N22*$N$3+O22*$O$3+P22*$P$3 -> 151162 | Y22: =B22*99+C22*$C$3+D22*$D$3+E22*$E$3+F22*$F$3+G22*$G$3+H22*$H$3+I22*$I$3+J22*$J$3+K22*$K$3+L22*$L$3+M22*$M$3+N22*$N$3+O22*$O$3+P22*$P$3 -> 162745
A23: 孙承飞 | B23: 168 | C23: 8 | D23: 780 | E23: 720 | F23: 1 | G23: 62 | J23: 26 | K23: 2 | R23: 2 | S23: 4 | U23: =SUM(C23:P23)-D23 -> 819 | V23: =SUM(B23:P23)-D23 -> 987 | W23: =B23+C23+E23+F23+G23*2+H23*3+I23*3+J23+K23*6+L23*5+M23+N23*5+O23*5+P23+Q23 -> 1059 | X23: =C23*$C$3+D23*$D$3+E23*$E$3+F23*$F$3+G23*$G$3+H23*$H$3+I23*$I$3+J23*$J$3+K23*$K$3+L23*$L$3+M23*$M$3+N23*$N$3+O23*$O$3+P23*$P$3 -> 94743 | Y23: =B23*99+C23*$C$3+D23*$D$3+E23*$E$3+F23*$F$3+G23*$G$3+H23*$H$3+I23*$I$3+J23*$J$3+K23*$K$3+L23*$L$3+M23*$M$3+N23*$N$3+O23*$O$3+P23*$P$3 -> 111375
A24: 赵希平 | B24: 207 | C24: 5 | D24: 510 | E24: 506 | G24: 88 | J24: 19 | K24: 15 | L24: 6 | R24: 4 | S24: 3 | U24: =SUM(C24:P24)-D24 -> 639 | V24: =SUM(B24:P24)-D24 -> 846 | W24: =B24+C24+E24+F24+G24*2+H24*3+I24*3+J24+K24*6+L24*5+M24+N24*5+O24*5+P24+Q24 -> 1033 | X24: =C24*$C$3+D24*$D$3+E24*$E$3+F24*$F$3+G24*$G$3+H24*$H$3+I24*$I$3+J24*$J$3+K24*$K$3+L24*$L$3+M24*$M$3+N24*$N$3+O24*$O$3+P24*$P$3 -> 80014 | Y24: =B24*99+C24*$C$3+D24*$D$3+E24*$E$3+F24*$F$3+G24*$G$3+H24*$H$3+I24*$I$3+J24*$J$3+K24*$K$3+L24*$L$3+M24*$M$3+N24*$N$3+O24*$O$3+P24*$P$3 -> 100507
A25: 李嘉鹏 | R25: 25 | U25: =SUM(C25:P25)-D25 -> 0 | V25: =SUM(B25:P25)-D25 -> 0 | W25: =B25+C25+E25+F25+G25*2+H25*3+I25*3+J25+K25*6+L25*5+M25+N25*5+O25*5+P25+Q25 -> 0 | X25: =C25*$C$3+D25*$D$3+E25*$E$3+F25*$F$3+G25*$G$3+H25*$H$3+I25*$I$3+J25*$J$3+K25*$K$3+L25*$L$3+M25*$M$3+N25*$N$3+O25*$O$3+P25*$P$3 -> 0 | Y25: =B25*99+C25*$C$3+D25*$D$3+E25*$E$3+F25*$F$3+G25*$G$3+H25*$H$3+I25*$I$3+J25*$J$3+K25*$K$3+L25*$L$3+M25*$M$3+N25*$N$3+O25*$O$3+P25*$P$3 -> 0
A26: 姚静雯 | R26: 25 | U26: =SUM(C26:P26)-D26 -> 0 | V26: =SUM(B26:P26)-D26 -> 0 | W26: =B26+C26+E26+F26+G26*2+H26*3+I26*3+J26+K26*6+L26*5+M26+N26*5+O26*5+P26+Q26 -> 0 | X26: =C26*$C$3+D26*$D$3+E26*$E$3+F26*$F$3+G26*$G$3+H26*$H$3+I26*$I$3+J26*$J$3+K26*$K$3+L26*$L$3+M26*$M$3+N26*$N$3+O26*$O$3+P26*$P$3 -> 0 | Y26: =B26*99+C26*$C$3+D26*$D$3+E26*$E$3+F26*$F$3+G26*$G$3+H26*$H$3+I26*$I$3+J26*$J$3+K26*$K$3+L26*$L$3+M26*$M$3+N26*$N$3+O26*$O$3+P26*$P$3 -> 0
A27: 李楠 | R27: 15 | U27: =SUM(C27:P27)-D27 -> 0 | V27: =SUM(B27:P27)-D27 -> 0 | W27: =B27+C27+E27+F27+G27*2+H27*3+I27*3+J27+K27*6+L27*5+M27+N27*5+O27*5+P27+Q27 -> 0 | X27: =C27*$C$3+D27*$D$3+E27*$E$3+F27*$F$3+G27*$G$3+H27*$H$3+I27*$I$3+J27*$J$3+K27*$K$3+L27*$L$3+M27*$M$3+N27*$N$3+O27*$O$3+P27*$P$3 -> 0 | Y27: =B27*99+C27*$C$3+D27*$D$3+E27*$E$3+F27*$F$3+G27*$G$3+H27*$H$3+I27*$I$3+J27*$J$3+K27*$K$3+L27*$L$3+M27*$M$3+N27*$N$3+O27*$O$3+P27*$P$3 -> 0
A28: 韩天福 | R28: 15 | U28: =SUM(C28:P28)-D28 -> 0 | V28: =SUM(B28:P28)-D28 -> 0 | W28: =B28+C28+E28+F28+G28*2+H28*3+I28*3+J28+K28*6+L28*5+M28+N28*5+O28*5+P28+Q28 -> 0 | X28: =C28*$C$3+D28*$D$3+E28*$E$3+F28*$F$3+G28*$G$3+H28*$H$3+I28*$I$3+J28*$J$3+K28*$K$3+L28*$L$3+M28*$M$3+N28*$N$3+O28*$O$3+P28*$P$3 -> 0 | Y28: =B28*99+C28*$C$3+D28*$D$3+E28*$E$3+F28*$F$3+G28*$G$3+H28*$H$3+I28*$I$3+J28*$J$3+K28*$K$3+L28*$L$3+M28*$M$3+N28*$N$3+O28*$O$3+P28*$P$3 -> 0
A29: 刘海燕 | B29: 33 | C29: 25 | D29: 325 | E29: 260 | G29: 92 | J29: 3 | U29: =SUM(C29:P29)-D29 -> 380 | V29: =SUM(B29:P29)-D29 -> 413 | W29: 0 | X29: =C29*$C$3+D29*$D$3+E29*$E$3+F29*$F$3+G29*$G$3+H29*$H$3+I29*$I$3+J29*$J$3+K29*$K$3+L29*$L$3+M29*$M$3+N29*$N$3+O29*$O$3+P29*$P$3 -> 55280.5 | Y29: =B29*99+C29*$C$3+D29*$D$3+E29*$E$3+F29*$F$3+G29*$G$3+H29*$H$3+I29*$I$3+J29*$J$3+K29*$K$3+L29*$L$3+M29*$M$3+N29*$N$3+O29*$O$3+P29*$P$3 -> 58547.5
U30: =SUM(B30:Q30) -> 0 | V30: =SUM(B30:P30)-D30 -> 0 | W30: =B30+C30+E30+F30+G30*2+H30*3+I30*3+J30+K30*6+L30*5+M30+N30*5+O30*5+P30+Q30 -> 0 | X30: =C30*$C$3+D30*$D$3+E30*$E$3+F30*$F$3+G30*$G$3+H30*$H$3+I30*$I$3+J30*$J$3+K30*$K$3+L30*$L$3+M30*$M$3+N30*$N$3+O30*$O$3+P30*$P$3 -> 0 | Y30: =B30*99+C30*$C$3+D30*$D$3+E30*$E$3+F30*$F$3+G30*$G$3+H30*$H$3+I30*$I$3+J30*$J$3+K30*$K$3+L30*$L$3+M30*$M$3+N30*$N$3+O30*$O$3+P30*$P$3 -> 0
A31: 工作量合计 | B31: =SUM(B4:B30) -> 4286 | C31: =SUM(C4:C30) -> 1010 | D31: =SUM(D4:D30) -> 11025 | E31: =SUM(E4:E30) -> 9427 | F31: =SUM(F4:F30) -> 4 | G31: =SUM(G4:G30) -> 2352 | H31: =SUM(H4:H30) -> 32 | I31: =SUM(I4:I30) -> 9 | ... U31: =SUM(U4:U30) -> 13297 | V31: =SUM(B31:P31)-D31 -> 17583 | W31: =SUM(W4:W30) -> 20839 | X31: =SUM(X4:X30) -> 1803794.5 | Y31: =B31*99+C31*$C$3+D31*$D$3+E31*$E$3+F31*$F$3+G31*$G$3+H31*$H$3+I31*$I$3+J31*$J$3+K31*$K$3+L31*$L$3+M31*$M$3+N31*$N$3+O31*$O$3+P31*$P$3 -> 2228108.5
A32: 收入合计 | B32: =B31*B3 -> 424314 | C32: =C31*C3 -> 133320 | D32: =D31*D3 -> 60637.5 | E32: =E31*E3 -> 933273 | F32: =F31*F3 -> 220 | G32: =G31*G3 -> 620928 | H32: =H31*H3 -> 9920 | I32: =I31*I3 -> 2574 | ... P32: =P31*P3 -> 0 | U32: - | V32: - | W32: - | X32: =SUM(C32:P32) -> 1803794.5 | Y32: =SUM(B32:P32) -> 2228108.5

Sheet 3月
A1: 2022年3月超声工作量
A2: 姓名 | B2: 体检例数 | C2: 腔内超声检查 | D2: 图文报告 | E2: 超声检查正常(包括双胎) | F2: 双胎加收 | G2: 脏器灰阶立体成象*2 | H2: 超声检查(胎儿系统) *3 | I2: 胎儿心脏超声 *3 | J2: 残余尿测定 | K2: 床旁彩超 *6 | L2: 床旁彩超加收 *5 | M2: B超常规检 | N2: 脏器声学造影 *5 | O2: 临床操作超声引导*5 | P2: 弹性成像 | Q2: 误时工作量例数 | R2: 疑难病例会诊例数 | S2: 夜班例数 | T2: 扣罚金额 | U2: 门住工作量合计 | V2: 门住体工作量合计 | W2: 绩效工作量 | X2: 门住收入合计 | Y2: 门住体总收入合计
B3: 99 | C3: 132 | D3: 5.5 | E3: 99 | F3: 55 | G3: 264 | H3: 310 | I3: 286 | J3: 55 | K3: 132 | L3: 33 | M3: 27.5 | N3: 143 | O3: 143 | P3: 55 | R3: 20 | S3: 50 | T3: 50-500
A4: 信吉伟 | B4: 15 | C4: 51 | D4: 505 | E4: 384 | F4: 2 | G4: 138 | H4: 36 | I4: 1 | J4: 1 | K4: 0 | L4: 0 | M4: 0 | N4: 11 | O4: 36 | P4: 0 | Q4: 80 | R4: 88 | U4: =SUM(C4:P4)-D4 -> 660 | V4: =SUM(B4:P4)-D4 -> 675 | W4: =B4+C4+E4+F4+G4*2+H4*3+I4*3+J4+K4*6+L4*5+M4+N4*5+O4*5+P4+Q4 -> 1155 | X4: =C4*$C$3+D4*$D$3+E4*$E$3+F4*$F$3+G4*$G$3+H4*$H$3+I4*$I$3+J4*$J$3+K4*$K$3+L4*$L$3+M4*$M$3+N4*$N$3+O4*$O$3+P4*$P$3 -> 102289.5 | Y4: =B4*99+C4*$C$3+D4*$D$3+E4*$E$3+F4*$F$3+G4*$G$3+H4*$H$3+I4*$I$3+J4*$J$3+K4*$K$3+L4*$L$3+M4*$M$3+N4*$N$3+O4*$O$3+P4*$P$3 -> 103774.5
A5: 刘思阳 | B5: 69 | D5: 595 | E5: 620 | G5: 97 | J5: 28 | R5: 8 | U5: =SUM(C5:P5)-D5 -> 745 | V5: =SUM(B5:P5)-D5 -> 814 | W5: =B5+C5+E5+F5+G5*2+H5*3+I5*3+J5+K5*6+L5*5+M5+N5*5+O5*5+P5+Q5 -> 911 | X5: =C5*$C$3+D5*$D$3+E5*$E$3+F5*$F$3+G5*$G$3+H5*$H$3+I5*$I$3+J5*$J$3+K5*$K$3+L5*$L$3+M5*$M$3+N5*$N$3+O5*$O$3+P5*$P$3 -> 91800.5 | Y5: =B5*99+C5*$C$3+D5*$D$3+E5*$E$3+F5*$F$3+G5*$G$3+H5*$H$3+I5*$I$3+J5*$J$3+K5*$K$3+L5*$L$3+M5*$M$3+N5*$N$3+O5*$O$3+P5*$P$3 -> 98631.5
A6: 邢卫军 | B6: 408 | C6: 105 | D6: 564 | E6: 365 | G6: 161 | J6: 3 | R6: 4 | U6: =SUM(C6:P6)-D6 -> 634 | V6: =SUM(B6:P6)-D6 -> 1042 | W6: =B6+C6+E6+F6+G6*2+H6*3+I6*3+J6+K6*6+L6*5+M6+N6*5+O6*5+P6+Q6 -> 1203 | X6: =C6*$C$3+D6*$D$3+E6*$E$3+F6*$F$3+G6*$G$3+H6*$H$3+I6*$I$3+J6*$J$3+K6*$K$3+L6*$L$3+M6*$M$3+N6*$N$3+O6*$O$3+P6*$P$3 -> 95766 | Y6: =B6*99+C6*$C$3+D6*$D$3+E6*$E$3+F6*$F$3+G6*$G$3+H6*$H$3+I6*$I$3+J6*$J$3+K6*$K$3+L6*$L$3+M6*$M$3+N6*$N$3+O6*$O$3+P6*$P$3 -> 136158
A7: 姜纯莲 | B7: 434 | C7: 169 | D7: 958 | E7: 659 | G7: 246 | J7: 8 | R7: 8 | U7: =SUM(C7:P7)-D7 -> 1082 | V7: =SUM(B7:P7)-D7 -> 1516 | W7: =B7+C7+E7+F7+G7*2+H7*3+I7*3+J7+K7*6+L7*5+M7+N7*5+O7*5+P7+Q7 -> 1762 | X7: =C7*$C$3+D7*$D$3+E7*$E$3+F7*$F$3+G7*$G$3+H7*$H$3+I7*$I$3+J7*$J$3+K7*$K$3+L7*$L$3+M7*$M$3+N7*$N$3+O7*$O$3+P7*$P$3 -> 158202 | Y7: =B7*99+C7*$C$3+D7*$D$3+E7*$E$3+F7*$F$3+G7*$G$3+H7*$H$3+I7*$I$3+J7*$J$3+K7*$K$3+L7*$L$3+M7*$M$3+N7*$N$3+O7*$O$3+P7*$P$3 -> 201168
A8: 王漠璇 | B8: 370 | C8: 158 | D8: 870 | E8: 547 | G8: 291 | J8: 9 | R8: 6 | U8: =SUM(C8:P8)-D8 -> 1005 | V8: =SUM(B8:P8)-D8 -> 1375 | W8: =B8+C8+E8+F8+G8*2+H8*3+I8*3+J8+K8*6+L8*5+M8+N8*5+O8*5+P8+Q8 -> 1666 | X8: =C8*$C$3+D8*$D$3+E8*$E$3+F8*$F$3+G8*$G$3+H8*$H$3+I8*$I$3+J8*$J$3+K8*$K$3+L8*$L$3+M8*$M$3+N8*$N$3+O8*$O$3+P8*$P$3 -> 157113 | Y8: =B8*99+C8*$C$3+D8*$D$3+E8*$E$3+F8*$F$3+G8*$G$3+H8*$H$3+I8*$I$3+J8*$J$3+K8*$K$3+L8*$L$3+M8*$M$3+N8*$N$3+O8*$O$3+P8*$P$3 -> 193743
A9: 汪亚新 | B9: 120 | D9: 374 | E9: 353 | G9: 54 | J9: 13 | R9: 8 | U9: =SUM(C9:P9)-D9 -> 420 | V9: =SUM(B9:P9)-D9 -> 540 | W9: =B9+C9+E9+F9+G9*2+H9*3+I9*3+J9+K9*6+L9*5+M9+N9*5+O9*5+P9+Q9 -> 594 | X9: =C9*$C$3+D9*$D$3+E9*$E$3+F9*$F$3+G9*$G$3+H9*$H$3+I9*$I$3+J9*$J$3+K9*$K$3+L9*$L$3+M9*$M$3+N9*$N$3+O9*$O$3+P9*$P$3 -> 51975 | Y9: =B9*99+C9*$C$3+D9*$D$3+E9*$E$3+F9*$F$3+G9*$G$3+H9*$H$3+I9*$I$3+J9*$J$3+K9*$K$3+L9*$L$3+M9*$M$3+N9*$N$3+O9*$O$3+P9*$P$3 -> 63855
A10: 李双生 | B10: 524 | C10: 4 | D10: 507 | E10: 519 | F10: 0 | G10: 102 | H10: 0 | I10: 0 | J10: 17 | K10: 33 | L10: 0 | M10: 0 | R10: 4 | S10: 3 | U10: =SUM(C10:P10)-D10 -> 675 | V10: =SUM(B10:P10)-D10 -> 1199 | W10: =B10+C10+E10+F10+G10*2+H10*3+I10*3+J10+K10*6+L10*5+M10+N10*5+O10*5+P10+Q10 -> 1466 | X10: =C10*$C$3+D10*$D$3+E10*$E$3+F10*$F$3+G10*$G$3+H10*$H$3+I10*$I$3+J10*$J$3+K10*$K$3+L10*$L$3+M10*$M$3+N10*$N$3+O10*$O$3+P10*$P$3 -> 86916.5 | Y10: =B10*99+C10*$C$3+D10*$D$3+E10*$E$3+F10*$F$3+G10*$G$3+H10*$H$3+I10*$I$3+J10*$J$3+K10*$K$3+L10*$L$3+M10*$M$3+N10*$N$3+O10*$O$3+P10*$P$3 -> 138792.5
A11: 董宝玲 | B11: 605 | C11: 31 | D11: 342 | E11: 303 | F11: 3 | G11: 82 | H11: 0 | I11: 0 | J11: 2 | K11: 16 | L11: 7 | S11: 2 | U11: =SUM(C11:P11)-D11 -> 444 | V11: =SUM(B11:P11)-D11 -> 1049 | W11: =B11+C11+E11+F11+G11*2+H11*3+I11*3+J11+K11*6+L11*5+M11+N11*5+O11*5+P11+Q11 -> 1239 | X11: =C11*$C$3+D11*$D$3+E11*$E$3+F11*$F$3+G11*$G$3+H11*$H$3+I11*$I$3+J11*$J$3+K11*$K$3+L11*$L$3+M11*$M$3+N11*$N$3+O11*$O$3+P11*$P$3 -> 60236 | Y11: =B11*99+C11*$C$3+D11*$D$3+E11*$E$3+F11*$F$3+G11*$G$3+H11*$H$3+I11*$I$3+J11*$J$3+K11*$K$3+L11*$L$3+M11*$M$3+N11*$N$3+O11*$O$3+P11*$P$3 -> 120131
A12: 周晓丽 | B12: 205 | C12: 38 | D12: 329 | E12: 294 | F12: 0 | G12: 60 | H12: 0 | I12: 4 | J12: 2 | K12: 15 | R12: 8 | S12: 3 | U12: =SUM(C12:P12)-D12 -> 413 | V12: =SUM(B12:P12)-D12 -> 618 | W12: =B12+C12+E12+F12+G12*2+H12*3+I12*3+J12+K12*6+L12*5+M12+N12*5+O12*5+P12+Q12 -> 761 | X12: =C12*$C$3+D12*$D$3+E12*$E$3+F12*$F$3+G12*$G$3+H12*$H$3+I12*$I$3+J12*$J$3+K12*$K$3+L12*$L$3+M12*$M$3+N12*$N$3+O12*$O$3+P12*$P$3 -> 55005.5 | Y12: =B12*99+C12*$C$3+D12*$D$3+E12*$E$3+F12*$F$3+G12*$G$3+H12*$H$3+I12*$I$3+J12*$J$3+K12*$K$3+L12*$L$3+M12*$M$3+N12*$N$3+O12*$O$3+P12*$P$3 -> 75300.5
A13: 刘炜 | B13: 248 | C13: 138 | D13: 718 | E13: 422 | F13: 1 | G13: 223 | H13: 9 | I13: 12 | J13: 2 | K13: 1 | L13: 0 | M13: 0 | N13: 7 | R13: 8 | U13: =SUM(C13:P13)-D13 -> 815 | V13: =SUM(B13:P13)-D13 -> 1063 | W13: =B13+C13+E13+F13+G13*2+H13*3+I13*3+J13+K13*6+L13*5+M13+N13*5+O13*5+P13+Q13 -> 1361 | X13: =C13*$C$3+D13*$D$3+E13*$E$3+F13*$F$3+G13*$G$3+H13*$H$3+I13*$I$3+J13*$J$3+K13*$K$3+L13*$L$3+M13*$M$3+N13*$N$3+O13*$O$3+P13*$P$3 -> 130335 | Y13: =B13*99+C13*$C$3+D13*$D$3+E13*$E$3+F13*$F$3+G13*$G$3+H13*$H$3+I13*$I$3+J13*$J$3+K13*$K$3+L13*$L$3+M13*$M$3+N13*$N$3+O13*$O$3+P13*$P$3 -> 154887
A14: 刘涛 | U14: =SUM(C14:P14)-D14 -> 0 | V14: =SUM(B14:P14)-D14 -> 0 | W14: =B14+C14+E14+F14+G14*2+H14*3+I14*3+J14+K14*6+L14*5+M14+N14*5+O14*5+P14+Q14 -> 0 | X14: =C14*$C$3+D14*$D$3+E14*$E$3+F14*$F$3+G14*$G$3+H14*$H$3+I14*$I$3+J14*$J$3+K14*$K$3+L14*$L$3+M14*$M$3+N14*$N$3+O14*$O$3+P14*$P$3 -> 0 | Y14: =B14*99+C14*$C$3+D14*$D$3+E14*$E$3+F14*$F$3+G14*$G$3+H14*$H$3+I14*$I$3+J14*$J$3+K14*$K$3+L14*$L$3+M14*$M$3+N14*$N$3+O14*$O$3+P14*$P$3 -> 0
A15: 朱凯 | B15: 251 | C15: 19 | D15: 774 | E15: 765 | F15: 1 | G15: 108 | H15: 0 | I15: 0 | J15: 11 | K15: 15 | L15: 0 | M15: 1 | N15: 0 | O15: 9 | R15: 6 | S15: 2 | U15: =SUM(C15:P15)-D15 -> 929 | V15: =SUM(B15:P15)-D15 -> 1180 | W15: =B15+C15+E15+F15+G15*2+H15*3+I15*3+J15+K15*6+L15*5+M15+N15*5+O15*5+P15+Q15 -> 1399 | X15: =C15*$C$3+D15*$D$3+E15*$E$3+F15*$F$3+G15*$G$3+H15*$H$3+I15*$I$3+J15*$J$3+K15*$K$3+L15*$L$3+M15*$M$3+N15*$N$3+O15*$O$3+P15*$P$3 -> 114966.5 | Y15: =B15*99+C15*$C$3+D15*$D$3+E15*$E$3+F15*$F$3+G15*$G$3+H15*$H$3+I15*$I$3+J15*$J$3+K15*$K$3+L15*$L$3+M15*$M$3+N15*$N$3+O15*$O$3+P15*$P$3 -> 139815.5
A16: 李晓莹 | B16: 432 | C16: 128 | D16: 857 | E16: 590 | G16: 251 | H16: 1 | J16: 5 | K16: 14 | L16: 2 | R16: 6 | S16: 3 | U16: =SUM(C16:P16)-D16 -> 991 | V16: =SUM(B16:P16)-D16 -> 1423 | W16: =B16+C16+E16+F16+G16*2+H16*3+I16*3+J16+K16*6+L16*5+M16+N16*5+O16*5+P16+Q16 -> 1754 | X16: =C16*$C$3+D16*$D$3+E16*$E$3+F16*$F$3+G16*$G$3+H16*$H$3+I16*$I$3+J16*$J$3+K16*$K$3+L16*$L$3+M16*$M$3+N16*$N$3+O16*$O$3+P16*$P$3 -> 148782.5 | Y16: =B16*99+C16*$C$3+D16*$D$3+E16*$E$3+F16*$F$3+G16*$G$3+H16*$H$3+I16*$I$3+J16*$J$3+K16*$K$3+L16*$L$3+M16*$M$3+N16*$N$3+O16*$O$3+P16*$P$3 -> 191550.5
A17: 孟凡伟 | B17: 317 | C17: 19 | D17: 430 | E17: 454 | F17: 0 | G17: 28 | H17: 0 | I17: 0 | J17: 10 | K17: 19 | L17: 0 | M17: 0 | N17: 0 | O17: 0 | R17: 4 | S17: 2 | U17: =SUM(C17:P17)-D17 -> 530 | V17: =SUM(B17:P17)-D17 -> 847 | W17: =B17+C17+E17+F17+G17*2+H17*3+I17*3+J17+K17*6+L17*5+M17+N17*5+O17*5+P17+Q17 -> 970 | X17: =C17*$C$3+D17*$D$3+E17*$E$3+F17*$F$3+G17*$G$3+H17*$H$3+I17*$I$3+J17*$J$3+K17*$K$3+L17*$L$3+M17*$M$3+N17*$N$3+O17*$O$3+P17*$P$3 -> 60269 | Y17: =B17*99+C17*$C$3+D17*$D$3+E17*$E$3+F17*$F$3+G17*$G$3+H17*$H$3+I17*$I$3+J17*$J$3+K17*$K$3+L17*$L$3+M17*$M$3+N17*$N$3+O17*$O$3+P17*$P$3 -> 91652
A18: 王桐 | B18: 345 | C18: 38 | D18: 241 | E18: 200 | F18: 1 | G18: 41 | H18: 0 | I18: 0 | J18: 1 | K18: 27 | L18: 0 | M18: 0 | N18: 0 | R18: 2 | S18: 2 | U18: =SUM(C18:P18)-D18 -> 308 | V18: =SUM(B18:P18)-D18 -> 653 | W18: =B18+C18+E18+F18+G18*2+H18*3+I18*3+J18+K18*6+L18*5+M18+N18*5+O18*5+P18+Q18 -> 829 | X18: =C18*$C$3+D18*$D$3+E18*$E$3+F18*$F$3+G18*$G$3+H18*$H$3+I18*$I$3+J18*$J$3+K18*$K$3+L18*$L$3+M18*$M$3+N18*$N$3+O18*$O$3+P18*$P$3 -> 40639.5 | Y18: =B18*99+C18*$C$3+D18*$D$3+E18*$E$3+F18*$F$3+G18*$G$3+H18*$H$3+I18*$I$3+J18*$J$3+K18*$K$3+L18*$L$3+M18*$M$3+N18*$N$3+O18*$O$3+P18*$P$3 -> 74794.5
A19: 程日 | B19: 553 | C19: 9 | D19: 502 | E19: 496 | F19: 0 | G19: 76 | H19: 0 | I19: 0 | J19: 14 | K19: 19 | L19: 0 | R19: 2 | S19: 3 | U19: =SUM(C19:P19)-D19 -> 614 | V19: =SUM(B19:P19)-D19 -> 1167 | W19: =B19+C19+E19+F19+G19*2+H19*3+I19*3+J19+K19*6+L19*5+M19+N19*5+O19*5+P19+Q19 -> 1338 | X19: =C19*$C$3+D19*$D$3+E19*$E$3+F19*$F$3+G19*$G$3+H19*$H$3+I19*$I$3+J19*$J$3+K19*$K$3+L19*$L$3+M19*$M$3+N19*$N$3+O19*$O$3+P19*$P$3 -> 76395 | Y19: =B19*99+C19*$C$3+D19*$D$3+E19*$E$3+F19*$F$3+G19*$G$3+H19*$H$3+I19*$I$3+J19*$J$3+K19*$K$3+L19*$L$3+M19*$M$3+N19*$N$3+O19*$O$3+P19*$P$3 -> 131142
A20: 洪森 | B20: 309 | C20: 5 | D20: 501 | E20: 479 | F20: 2 | G20: 91 | H20: 0 | I20: 0 | J20: 13 | K20: 33 | L20: 11 | M20: 0 | R20: 8 | S20: 2 | U20: =SUM(C20:P20)-D20 -> 634 | V20: =SUM(B20:P20)-D20 -> 943 | W20: =B20+C20+E20+F20+G20*2+H20*3+I20*3+J20+K20*6+L20*5+M20+N20*5+O20*5+P20+Q20 -> 1243 | X20: =C20*$C$3+D20*$D$3+E20*$E$3+F20*$F$3+G20*$G$3+H20*$H$3+I20*$I$3+J20*$J$3+K20*$K$3+L20*$L$3+M20*$M$3+N20*$N$3+O20*$O$3+P20*$P$3 -> 80404.5 | Y20: =B20*99+C20*$C$3+D20*$D$3+E20*$E$3+F20*$F$3+G20*$G$3+H20*$H$3+I20*$I$3+J20*$J$3+K20*$K$3+L20*$L$3+M20*$M$3+N20*$N$3+O20*$O$3+P20*$P$3 -> 110995.5
A21: 马延梁 | B21: 597 | C21: 7 | D21: 879 | E21: 858 | F21: 2 | G21: 94 | H21: 0 | I21: 0 | J21: 28 | K21: 19 | L21: 8 | M21: 0 | R21: 8 | S21: 3 | U21: =SUM(C21:P21)-D21 -> 1016 | V21: =SUM(B21:P21)-D21 -> 1613 | W21: =B21+C21+E21+F21+G21*2+H21*3+I21*3+J21+K21*6+L21*5+M21+N21*5+O21*5+P21+Q21 -> 1834 | X21: =C21*$C$3+D21*$D$3+E21*$E$3+F21*$F$3+G21*$G$3+H21*$H$3+I21*$I$3+J21*$J$3+K21*$K$3+L21*$L$3+M21*$M$3+N21*$N$3+O21*$O$3+P21*$P$3 -> 119938.5 | Y21: =B21*99+C21*$C$3+D21*$D$3+E21*$E$3+F21*$F$3+G21*$G$3+H21*$H$3+I21*$I$3+J21*$J$3+K21*$K$3+L21*$L$3+M21*$M$3+N21*$N$3+O21*$O$3+P21*$P$3 -> 179041.5
A22: 史嘉琳 | B22: 395 | C22: 142 | D22: 944 | E22: 807 | F22: 1 | G22: 232 | H22: 0 | I22: 0 | J22: 11 | K22: 0 | R22: 8 | U22: =SUM(C22:P22)-D22 -> 1193 | V22: =SUM(B22:P22)-D22 -> 1588 | W22: =B22+C22+E22+F22+G22*2+H22*3+I22*3+J22+K22*6+L22*5+M22+N22*5+O22*5+P22+Q22 -> 1820 | X22: =C22*$C$3+D22*$D$3+E22*$E$3+F22*$F$3+G22*$G$3+H22*$H$3+I22*$I$3+J22*$J$3+K22*$K$3+L22*$L$3+M22*$M$3+N22*$N$3+O22*$O$3+P22*$P$3 -> 165737 | Y22: =B22*99+C22*$C$3+D22*$D$3+E22*$E$3+F22*$F$3+G22*$G$3+H22*$H$3+I22*$I$3+J22*$J$3+K22*$K$3+L22*$L$3+M22*$M$3+N22*$N$3+O22*$O$3+P22*$P$3 -> 204842
A23: 孙承飞 | B23: 355 | C23: 4 | D23: 524 | E23: 575 | F23: 1 | G23: 54 | H23: 0 | I23: 0 | J23: 6 | K23: 27 | L23: 6 | R23: 6 | S23: 3 | U23: =SUM(C23:P23)-D23 -> 673 | V23: =SUM(B23:P23)-D23 -> 1028 | W23: =B23+C23+E23+F23+G23*2+H23*3+I23*3+J23+K23*6+L23*5+M23+N23*5+O23*5+P23+Q23 -> 1241 | X23: =C23*$C$3+D23*$D$3+E23*$E$3+F23*$F$3+G23*$G$3+H23*$H$3+I23*$I$3+J23*$J$3+K23*$K$3+L23*$L$3+M23*$M$3+N23*$N$3+O23*$O$3+P23*$P$3 -> 78738 | Y23: =B23*99+C23*$C$3+D23*$D$3+E23*$E$3+F23*$F$3+G23*$G$3+H23*$H$3+I23*$I$3+J23*$J$3+K23*$K$3+L23*$L$3+M23*$M$3+N23*$N$3+O23*$O$3+P23*$P$3 -> 113883
A24: 赵希平 | B24: 234 | C24: 4 | D24: 434 | E24: 440 | F24: 0 | G24: 56 | H24: 0 | I24: 0 | J24: 11 | K24: 17 | L24: 3 | M24: 0 | R24: 8 | S24: 3 | U24: =SUM(C24:P24)-D24 -> 531 | V24: =SUM(B24:P24)-D24 -> 765 | W24: =B24+C24+E24+F24+G24*2+H24*3+I24*3+J24+K24*6+L24*5+M24+N24*5+O24*5+P24+Q24 -> 918 | X24: =C24*$C$3+D24*$D$3+E24*$E$3+F24*$F$3+G24*$G$3+H24*$H$3+I24*$I$3+J24*$J$3+K24*$K$3+L24*$L$3+M24*$M$3+N24*$N$3+O24*$O$3+P24*$P$3 -> 64207 | Y24: =B24*99+C24*$C$3+D24*$D$3+E24*$E$3+F24*$F$3+G24*$G$3+H24*$H$3+I24*$I$3+J24*$J$3+K24*$K$3+L24*$L$3+M24*$M$3+N24*$N$3+O24*$O$3+P24*$P$3 -> 87373
A25: 李嘉鹏 | U25: =SUM(C25:P25)-D25 -> 0 | V25: =SUM(B25:P25)-D25 -> 0 | W25: =B25+C25+E25+F25+G25*2+H25*3+I25*3+J25+K25*6+L25*5+M25+N25*5+O25*5+P25+Q25 -> 0 | X25: =C25*$C$3+D25*$D$3+E25*$E$3+F25*$F$3+G25*$G$3+H25*$H$3+I25*$I$3+J25*$J$3+K25*$K$3+L25*$L$3+M25*$M$3+N25*$N$3+O25*$O$3+P25*$P$3 -> 0 | Y25: =B25*99+C25*$C$3+D25*$D$3+E25*$E$3+F25*$F$3+G25*$G$3+H25*$H$3+I25*$I$3+J25*$J$3+K25*$K$3+L25*$L$3+M25*$M$3+N25*$N$3+O25*$O$3+P25*$P$3 -> 0
A26: 姚静雯 | U26: =SUM(C26:P26)-D26 -> 0 | V26: =SUM(B26:P26)-D26 -> 0 | W26: =B26+C26+E26+F26+G26*2+H26*3+I26*3+J26+K26*6+L26*5+M26+N26*5+O26*5+P26+Q26 -> 0 | X26: =C26*$C$3+D26*$D$3+E26*$E$3+F26*$F$3+G26*$G$3+H26*$H$3+I26*$I$3+J26*$J$3+K26*$K$3+L26*$L$3+M26*$M$3+N26*$N$3+O26*$O$3+P26*$P$3 -> 0 | Y26: =B26*99+C26*$C$3+D26*$D$3+E26*$E$3+F26*$F$3+G26*$G$3+H26*$H$3+I26*$I$3+J26*$J$3+K26*$K$3+L26*$L$3+M26*$M$3+N26*$N$3+O26*$O$3+P26*$P$3 -> 0
A27: 李楠 | U27: =SUM(C27:P27)-D27 -> 0 | V27: =SUM(B27:P27)-D27 -> 0 | W27: =B27+C27+E27+F27+G27*2+H27*3+I27*3+J27+K27*6+L27*5+M27+N27*5+O27*5+P27+Q27 -> 0 | X27: =C27*$C$3+D27*$D$3+E27*$E$3+F27*$F$3+G27*$G$3+H27*$H$3+I27*$I$3+J27*$J$3+K27*$K$3+L27*$L$3+M27*$M$3+N27*$N$3+O27*$O$3+P27*$P$3 -> 0 | Y27: =B27*99+C27*$C$3+D27*$D$3+E27*$E$3+F27*$F$3+G27*$G$3+H27*$H$3+I27*$I$3+J27*$J$3+K27*$K$3+L27*$L$3+M27*$M$3+N27*$N$3+O27*$O$3+P27*$P$3 -> 0
A28: 韩天福 | U28: =SUM(C28:P28)-D28 -> 0 | V28: =SUM(B28:P28)-D28 -> 0 | W28: =B28+C28+E28+F28+G28*2+H28*3+I28*3+J28+K28*6+L28*5+M28+N28*5+O28*5+P28+Q28 -> 0 | X28: =C28*$C$3+D28*$D$3+E28*$E$3+F28*$F$3+G28*$G$3+H28*$H$3+I28*$I$3+J28*$J$3+K28*$K$3+L28*$L$3+M28*$M$3+N28*$N$3+O28*$O$3+P28*$P$3 -> 0 | Y28: =B28*99+C28*$C$3+D28*$D$3+E28*$E$3+F28*$F$3+G28*$G$3+H28*$H$3+I28*$I$3+J28*$J$3+K28*$K$3+L28*$L$3+M28*$M$3+N28*$N$3+O28*$O$3+P28*$P$3 -> 0
A29: 刘海燕 | B29: 80 | C29: 67 | D29: 765 | E29: 677 | F29: 0 | G29: 182 | H29: 0 | I29: 0 | J29: 8 | K29: 0 | L29: 0 | M29: 0 | N29: 0 | O29: 0 | P29: 3 | U29: =SUM(C29:P29)-D29 -> 937 | V29: =SUM(B29:P29)-D29 -> 1017 | W29: 0 | X29: =C29*$C$3+D29*$D$3+E29*$E$3+F29*$F$3+G29*$G$3+H29*$H$3+I29*$I$3+J29*$J$3+K29*$K$3+L29*$L$3+M29*$M$3+N29*$N$3+O29*$O$3+P29*$P$3 -> 128727.5 | Y29: =B29*99+C29*$C$3+D29*$D$3+E29*$E$3+F29*$F$3+G29*$G$3+H29*$H$3+I29*$I$3+J29*$J$3+K29*$K$3+L29*$L$3+M29*$M$3+N29*$N$3+O29*$O$3+P29*$P$3 -> 136647.5
U30: =SUM(B30:Q30) -> 0 | V30: =SUM(B30:P30)-D30 -> 0 | W30: =B30+C30+E30+F30+G30*2+H30*3+I30*3+J30+K30*6+L30*5+M30+N30*5+O30*5+P30+Q30 -> 0 | X30: =C30*$C$3+D30*$D$3+E30*$E$3+F30*$F$3+G30*$G$3+H30*$H$3+I30*$I$3+J30*$J$3+K30*$K$3+L30*$L$3+M30*$M$3+N30*$N$3+O30*$O$3+P30*$P$3 -> 0 | Y30: =B30*99+C30*$C$3+D30*$D$3+E30*$E$3+F30*$F$3+G30*$G$3+H30*$H$3+I30*$I$3+J30*$J$3+K30*$K$3+L30*$L$3+M30*$M$3+N30*$N$3+O30*$O$3+P30*$P$3 -> 0
A31: 工作量合计 | B31: =SUM(B4:B30) -> 6866 | C31: =SUM(C4:C30) -> 1136 | D31: =SUM(D4:D30) -> 12613 | E31: =SUM(E4:E30) -> 10807 | F31: =SUM(F4:F30) -> 14 | G31: =SUM(G4:G30) -> 2667 | H31: =SUM(H4:H30) -> 46 | I31: =SUM(I4:I30) -> 17 | ... U31: =SUM(U4:U30) -> 15249 | V31: =SUM(B31:P31)-D31 -> 22115 | W31: =SUM(W4:W30) -> 25464 | X31: =SUM(X4:X30) -> 2068444 | Y31: =B31*99+C31*$C$3+D31*$D$3+E31*$E$3+F31*$F$3+G31*$G$3+H31*$H$3+I31*$I$3+J31*$J$3+K31*$K$3+L31*$L$3+M31*$M$3+N31*$N$3+O31*$O$3+P31*$P$3 -> 2748178
A32: 收入合计 | B32: =B31*B3 -> 679734 | C32: =C31*C3 -> 149952 | D32: =D31*D3 -> 69371.5 | E32: =E31*E3 -> 1069893 | F32: =F31*F3 -> 770 | G32: =G31*G3 -> 704088 | H32: =H31*H3 -> 14260 | I32: =I31*I3 -> 4862 | ... P32: =P31*P3 -> 165 | U32: - | V32: - | W32: - | X32: =SUM(C32:P32) -> 2068444 | Y32: =SUM(B32:P32) -> 2748178

Sheet 4月
A1: 2022年4月超声工作量
A2: 姓名 | B2: 体检例数 | C2: 腔内超声检查 | D2: 图文报告 | E2: 超声检查正常(包括双胎) | F2: 双胎加收 | G2: 脏器灰阶立体成象*2 | H2: 超声检查(胎儿系统) *3 | I2: 胎儿心脏超声 *3 | J2: 残余尿测定 | K2: 床旁彩超 *6 | L2: 床旁彩超加收 *5 | M2: B超常规检 | N2: 脏器声学造影 *5 | O2: 临床操作超声引导*5 | P2: 弹性成像 | Q2: 误时工作量例数 | R2: 疑难病例会诊例数 | S2: 夜班例数 | T2: 扣罚金额 | U2: 门住工作量合计 | V2: 门住体工作量合计 | W2: 绩效工作量 | X2: 门住收入合计 | Y2: 门住体总收入合计
B3: 99 | C3: 132 | D3: 5.5 | E3: 99 | F3: 55 | G3: 264 | H3: 310 | I3: 286 | J3: 55 | K3: 132 | L3: 33 | M3: 27.5 | N3: 143 | O3: 143 | P3: 55 | R3: 20 | S3: 50 | T3: 50-500
A4: 信吉伟 | B4: 23 | C4: 54 | D4: 556 | E4: 432 | G4: 165 | H4: 41 | I4: 13 | J4: 4 | N4: 6 | O4: 39 | Q4: 270 | R4: 111 | U4: =SUM(C4:P4)-D4 -> 754 | V4: =SUM(B4:P4)-D4 -> 777 | W4: =B4+C4+E4+F4+G4*2+H4*3+I4*3+J4+K4*6+L4*5+M4+N4*5+O4*5+P4+Q4 -> 1500 | X4: =C4*$C$3+D4*$D$3+E4*$E$3+F4*$F$3+G4*$G$3+H4*$H$3+I4*$I$3+J4*$J$3+K4*$K$3+L4*$L$3+M4*$M$3+N4*$N$3+O4*$O$3+P4*$P$3 -> 119597 | Y4: =B4*99+C4*$C$3+D4*$D$3+E4*$E$3+F4*$F$3+G4*$G$3+H4*$H$3+I4*$I$3+J4*$J$3+K4*$K$3+L4*$L$3+M4*$M$3+N4*$N$3+O4*$O$3+P4*$P$3 -> 121874
A5: 刘思阳 | B5: 144 | D5: 510 | E5: 512 | G5: 98 | J5: 30 | K5: 1 | R5: 10 | U5: =SUM(C5:P5)-D5 -> 641 | V5: =SUM(B5:P5)-D5 -> 785 | W5: =B5+C5+E5+F5+G5*2+H5*3+I5*3+J5+K5*6+L5*5+M5+N5*5+O5*5+P5+Q5 -> 888 | X5: =C5*$C$3+D5*$D$3+E5*$E$3+F5*$F$3+G5*$G$3+H5*$H$3+I5*$I$3+J5*$J$3+K5*$K$3+L5*$L$3+M5*$M$3+N5*$N$3+O5*$O$3+P5*$P$3 -> 81147 | Y5: =B5*99+C5*$C$3+D5*$D$3+E5*$E$3+F5*$F$3+G5*$G$3+H5*$H$3+I5*$I$3+J5*$J$3+K5*$K$3+L5*$L$3+M5*$M$3+N5*$N$3+O5*$O$3+P5*$P$3 -> 95403
A6: 邢卫军 | B6: 255 | C6: 104 | D6: 501 | E6: 339 | G6: 124 | J6: 2 | R6: 10 | U6: =SUM(C6:P6)-D6 -> 569 | V6: =SUM(B6:P6)-D6 -> 824 | W6: =B6+C6+E6+F6+G6*2+H6*3+I6*3+J6+K6*6+L6*5+M6+N6*5+O6*5+P6+Q6 -> 948 | X6: =C6*$C$3+D6*$D$3+E6*$E$3+F6*$F$3+G6*$G$3+H6*$H$3+I6*$I$3+J6*$J$3+K6*$K$3+L6*$L$3+M6*$M$3+N6*$N$3+O6*$O$3+P6*$P$3 -> 82890.5 | Y6: =B6*99+C6*$C$3+D6*$D$3+E6*$E$3+F6*$F$3+G6*$G$3+H6*$H$3+I6*$I$3+J6*$J$3+K6*$K$3+L6*$L$3+M6*$M$3+N6*$N$3+O6*$O$3+P6*$P$3 -> 108135.5
A7: 姜纯莲 | B7: 423 | C7: 116 | D7: 693 | E7: 524 | G7: 167 | J7: 7 | R7: 4 | U7: =SUM(C7:P7)-D7 -> 814 | V7: =SUM(B7:P7)-D7 -> 1237 | W7: =B7+C7+E7+F7+G7*2+H7*3+I7*3+J7+K7*6+L7*5+M7+N7*5+O7*5+P7+Q7 -> 1404 | X7: =C7*$C$3+D7*$D$3+E7*$E$3+F7*$F$3+G7*$G$3+H7*$H$3+I7*$I$3+J7*$J$3+K7*$K$3+L7*$L$3+M7*$M$3+N7*$N$3+O7*$O$3+P7*$P$3 -> 115472.5 | Y7: =B7*99+C7*$C$3+D7*$D$3+E7*$E$3+F7*$F$3+G7*$G$3+H7*$H$3+I7*$I$3+J7*$J$3+K7*$K$3+L7*$L$3+M7*$M$3+N7*$N$3+O7*$O$3+P7*$P$3 -> 157349.5
A8: 王漠璇 | B8: 335 | C8: 141 | D8: 626 | E8: 345 | F8: 1 | G8: 197 | J8: 4 | R8: 8 | U8: =SUM(C8:P8)-D8 -> 688 | V8: =SUM(B8:P8)-D8 -> 1023 | W8: =B8+C8+E8+F8+G8*2+H8*3+I8*3+J8+K8*6+L8*5+M8+N8*5+O8*5+P8+Q8 -> 1220 | X8: =C8*$C$3+D8*$D$3+E8*$E$3+F8*$F$3+G8*$G$3+H8*$H$3+I8*$I$3+J8*$J$3+K8*$K$3+L8*$L$3+M8*$M$3+N8*$N$3+O8*$O$3+P8*$P$3 -> 108493 | Y8: =B8*99+C8*$C$3+D8*$D$3+E8*$E$3+F8*$F$3+G8*$G$3+H8*$H$3+I8*$I$3+J8*$J$3+K8*$K$3+L8*$L$3+M8*$M$3+N8*$N$3+O8*$O$3+P8*$P$3 -> 141658
A9: 汪亚新 | B9: 31 | D9: 362 | E9: 333 | G9: 57 | J9: 8 | R9: 8 | U9: =SUM(C9:P9)-D9 -> 398 | V9: =SUM(B9:P9)-D9 -> 429 | W9: =B9+C9+E9+F9+G9*2+H9*3+I9*3+J9+K9*6+L9*5+M9+N9*5+O9*5+P9+Q9 -> 486 | X9: =C9*$C$3+D9*$D$3+E9*$E$3+F9*$F$3+G9*$G$3+H9*$H$3+I9*$I$3+J9*$J$3+K9*$K$3+L9*$L$3+M9*$M$3+N9*$N$3+O9*$O$3+P9*$P$3 -> 50446 | Y9: =B9*99+C9*$C$3+D9*$D$3+E9*$E$3+F9*$F$3+G9*$G$3+H9*$H$3+I9*$I$3+J9*$J$3+K9*$K$3+L9*$L$3+M9*$M$3+N9*$N$3+O9*$O$3+P9*$P$3 -> 53515
A10: 李双生 | B10: 144 | D10: 498 | E10: 532 | G10: 92 | J10: 22 | K10: 17 | R10: 2 | S10: 3 | U10: =SUM(C10:P10)-D10 -> 663 | V10: =SUM(B10:P10)-D10 -> 807 | W10: =B10+C10+E10+F10+G10*2+H10*3+I10*3+J10+K10*6+L10*5+M10+N10*5+O10*5+P10+Q10 -> 984 | X10: =C10*$C$3+D10*$D$3+E10*$E$3+F10*$F$3+G10*$G$3+H10*$H$3+I10*$I$3+J10*$J$3+K10*$K$3+L10*$L$3+M10*$M$3+N10*$N$3+O10*$O$3+P10*$P$3 -> 83149 | Y10: =B10*99+C10*$C$3+D10*$D$3+E10*$E$3+F10*$F$3+G10*$G$3+H10*$H$3+I10*$I$3+J10*$J$3+K10*$K$3+L10*$L$3+M10*$M$3+N10*$N$3+O10*$O$3+P10*$P$3 -> 97405
A11: 董宝玲 | B11: 185 | C11: 70 | D11: 509 | E11: 392 | G11: 102 | J11: 7 | K11: 18 | L11: 7 | S11: 4 | U11: =SUM(C11:P11)-D11 -> 596 | V11: =SUM(B11:P11)-D11 -> 781 | W11: =B11+C11+E11+F11+G11*2+H11*3+I11*3+J11+K11*6+L11*5+M11+N11*5+O11*5+P11+Q11 -> 1001 | X11: =C11*$C$3+D11*$D$3+E11*$E$3+F11*$F$3+G11*$G$3+H11*$H$3+I11*$I$3+J11*$J$3+K11*$K$3+L11*$L$3+M11*$M$3+N11*$N$3+O11*$O$3+P11*$P$3 -> 80767.5 | Y11: =B11*99+C11*$C$3+D11*$D$3+E11*$E$3+F11*$F$3+G11*$G$3+H11*$H$3+I11*$I$3+J11*$J$3+K11*$K$3+L11*$L$3+M11*$M$3+N11*$N$3+O11*$O$3+P11*$P$3 -> 99082.5
A12: 周晓丽 | B12: 227 | C12: 42 | D12: 320 | E12: 245 | G12: 81 | H12: 1 | I12: 1 | J12: 2 | K12: 16 | R12: 9 | S12: 2 | U12: =SUM(C12:P12)-D12 -> 388 | V12: =SUM(B12:P12)-D12 -> 615 | W12: =B12+C12+E12+F12+G12*2+H12*3+I12*3+J12+K12*6+L12*5+M12+N12*5+O12*5+P12+Q12 -> 780 | X12: =C12*$C$3+D12*$D$3+E12*$E$3+F12*$F$3+G12*$G$3+H12*$H$3+I12*$I$3+J12*$J$3+K12*$K$3+L12*$L$3+M12*$M$3+N12*$N$3+O12*$O$3+P12*$P$3 -> 55761 | Y12: =B12*99+C12*$C$3+D12*$D$3+E12*$E$3+F12*$F$3+G12*$G$3+H12*$H$3+I12*$I$3+J12*$J$3+K12*$K$3+L12*$L$3+M12*$M$3+N12*$N$3+O12*$O$3+P12*$P$3 -> 78234
A13: 刘炜 | B13: 130 | C13: 76 | D13: 531 | E13: 363 | F13: 1 | G13: 157 | H13: 6 | I13: 13 | J13: 4 | N13: 2 | R13: 7 | U13: =SUM(C13:P13)-D13 -> 622 | V13: =SUM(B13:P13)-D13 -> 752 | W13: =B13+C13+E13+F13+G13*2+H13*3+I13*3+J13+K13*6+L13*5+M13+N13*5+O13*5+P13+Q13 -> 955 | X13: =C13*$C$3+D13*$D$3+E13*$E$3+F13*$F$3+G13*$G$3+H13*$H$3+I13*$I$3+J13*$J$3+K13*$K$3+L13*$L$3+M13*$M$3+N13*$N$3+O13*$O$3+P13*$P$3 -> 96476.5 | Y13: =B13*99+C13*$C$3+D13*$D$3+E13*$E$3+F13*$F$3+G13*$G$3+H13*$H$3+I13*$I$3+J13*$J$3+K13*$K$3+L13*$L$3+M13*$M$3+N13*$N$3+O13*$O$3+P13*$P$3 -> 109346.5
A14: 刘涛 | U14: =SUM(C14:P14)-D14 -> 0 | V14: =SUM(B14:P14)-D14 -> 0 | W14: =B14+C14+E14+F14+G14*2+H14*3+I14*3+J14+K14*6+L14*5+M14+N14*5+O14*5+P14+Q14 -> 0 | X14: =C14*$C$3+D14*$D$3+E14*$E$3+F14*$F$3+G14*$G$3+H14*$H$3+I14*$I$3+J14*$J$3+K14*$K$3+L14*$L$3+M14*$M$3+N14*$N$3+O14*$O$3+P14*$P$3 -> 0 | Y14: =B14*99+C14*$C$3+D14*$D$3+E14*$E$3+F14*$F$3+G14*$G$3+H14*$H$3+I14*$I$3+J14*$J$3+K14*$K$3+L14*$L$3+M14*$M$3+N14*$N$3+O14*$O$3+P14*$P$3 -> 0
A15: 朱凯 | B15: 190 | C15: 15 | D15: 449 | E15: 424 | G15: 85 | J15: 11 | K15: 20 | L15: 3 | O15: 7 | Q15: 135 | R15: 48 | S15: 3 | U15: =SUM(C15:P15)-D15 -> 565 | V15: =SUM(B15:P15)-D15 -> 755 | W15: =B15+C15+E15+F15+G15*2+H15*3+I15*3+J15+K15*6+L15*5+M15+N15*5+O15*5+P15+Q15 -> 1115 | X15: =C15*$C$3+D15*$D$3+E15*$E$3+F15*$F$3+G15*$G$3+H15*$H$3+I15*$I$3+J15*$J$3+K15*$K$3+L15*$L$3+M15*$M$3+N15*$N$3+O15*$O$3+P15*$P$3 -> 73210.5 | Y15: =B15*99+C15*$C$3+D15*$D$3+E15*$E$3+F15*$F$3+G15*$G$3+H15*$H$3+I15*$I$3+J15*$J$3+K15*$K$3+L15*$L$3+M15*$M$3+N15*$N$3+O15*$O$3+P15*$P$3 -> 92020.5
A16: 李晓莹 | B16: 291 | C16: 80 | D16: 617 | E16: 550 | F16: 2 | G16: 147 | J16: 2 | K16: 13 | L16: 5 | R16: 8 | S16: 2 | U16: =SUM(C16:P16)-D16 -> 799 | V16: =SUM(B16:P16)-D16 -> 1090 | W16: =B16+C16+E16+F16+G16*2+H16*3+I16*3+J16+K16*6+L16*5+M16+N16*5+O16*5+P16+Q16 -> 1322 | X16: =C16*$C$3+D16*$D$3+E16*$E$3+F16*$F$3+G16*$G$3+H16*$H$3+I16*$I$3+J16*$J$3+K16*$K$3+L16*$L$3+M16*$M$3+N16*$N$3+O16*$O$3+P16*$P$3 -> 109312.5 | Y16: =B16*99+C16*$C$3+D16*$D$3+E16*$E$3+F16*$F$3+G16*$G$3+H16*$H$3+I16*$I$3+J16*$J$3+K16*$K$3+L16*$L$3+M16*$M$3+N16*$N$3+O16*$O$3+P16*$P$3 -> 138121.5
A17: 孟凡伟 | B17: 324 | C17: 3 | D17: 504 | E17: 511 | G17: 64 | J17: 20 | K17: 20 | R17: 8 | S17: 3 | U17: =SUM(C17:P17)-D17 -> 618 | V17: =SUM(B17:P17)-D17 -> 942 | W17: =B17+C17+E17+F17+G17*2+H17*3+I17*3+J17+K17*6+L17*5+M17+N17*5+O17*5+P17+Q17 -> 1106 | X17: =C17*$C$3+D17*$D$3+E17*$E$3+F17*$F$3+G17*$G$3+H17*$H$3+I17*$I$3+J17*$J$3+K17*$K$3+L17*$L$3+M17*$M$3+N17*$N$3+O17*$O$3+P17*$P$3 -> 74393 | Y17: =B17*99+C17*$C$3+D17*$D$3+E17*$E$3+F17*$F$3+G17*$G$3+H17*$H$3+I17*$I$3+J17*$J$3+K17*$K$3+L17*$L$3+M17*$M$3+N17*$N$3+O17*$O$3+P17*$P$3 -> 106469
A18: 王桐 | B18: 277 | C18: 44 | D18: 298 | E18: 244 | G18: 63 | K18: 10 | R18: 4 | S18: 3 | U18: =SUM(C18:P18)-D18 -> 361 | V18: =SUM(B18:P18)-D18 -> 638 | W18: =B18+C18+E18+F18+G18*2+H18*3+I18*3+J18+K18*6+L18*5+M18+N18*5+O18*5+P18+Q18 -> 751 | X18: =C18*$C$3+D18*$D$3+E18*$E$3+F18*$F$3+G18*$G$3+H18*$H$3+I18*$I$3+J18*$J$3+K18*$K$3+L18*$L$3+M18*$M$3+N18*$N$3+O18*$O$3+P18*$P$3 -> 49555 | Y18: =B18*99+C18*$C$3+D18*$D$3+E18*$E$3+F18*$F$3+G18*$G$3+H18*$H$3+I18*$I$3+J18*$J$3+K18*$K$3+L18*$L$3+M18*$M$3+N18*$N$3+O18*$O$3+P18*$P$3 -> 76978
A19: 程日 | B19: 433 | C19: 5 | D19: 534 | E19: 588 | G19: 43 | J19: 15 | K19: 19 | R19: 4 | S19: 1 | U19: =SUM(C19:P19)-D19 -> 670 | V19: =SUM(B19:P19)-D19 -> 1103 | W19: =B19+C19+E19+F19+G19*2+H19*3+I19*3+J19+K19*6+L19*5+M19+N19*5+O19*5+P19+Q19 -> 1241 | X19: =C19*$C$3+D19*$D$3+E19*$E$3+F19*$F$3+G19*$G$3+H19*$H$3+I19*$I$3+J19*$J$3+K19*$K$3+L19*$L$3+M19*$M$3+N19*$N$3+O19*$O$3+P19*$P$3 -> 76494 | Y19: =B19*99+C19*$C$3+D19*$D$3+E19*$E$3+F19*$F$3+G19*$G$3+H19*$H$3+I19*$I$3+J19*$J$3+K19*$K$3+L19*$L$3+M19*$M$3+N19*$N$3+O19*$O$3+P19*$P$3 -> 119361
A20: 洪森 | B20: 212 | C20: 4 | D20: 408 | E20: 430 | G20: 33 | J20: 10 | K20: 26 | L20: 3 | R20: 8 | S20: 3 | U20: =SUM(C20:P20)-D20 -> 506 | V20: =SUM(B20:P20)-D20 -> 718 | W20: =B20+C20+E20+F20+G20*2+H20*3+I20*3+J20+K20*6+L20*5+M20+N20*5+O20*5+P20+Q20 -> 893 | X20: =C20*$C$3+D20*$D$3+E20*$E$3+F20*$F$3+G20*$G$3+H20*$H$3+I20*$I$3+J20*$J$3+K20*$K$3+L20*$L$3+M20*$M$3+N20*$N$3+O20*$O$3+P20*$P$3 -> 58135 | Y20: =B20*99+C20*$C$3+D20*$D$3+E20*$E$3+F20*$F$3+G20*$G$3+H20*$H$3+I20*$I$3+J20*$J$3+K20*$K$3+L20*$L$3+M20*$M$3+N20*$N$3+O20*$O$3+P20*$P$3 -> 79123
A21: 马延梁 | B21: 370 | C21: 14 | D21: 825 | E21: 858 | G21: 100 | J21: 20 | K21: 18 | L21: 2 | R21: 8 | S21: 2 | U21: =SUM(C21:P21)-D21 -> 1012 | V21: =SUM(B21:P21)-D21 -> 1382 | W21: =B21+C21+E21+F21+G21*2+H21*3+I21*3+J21+K21*6+L21*5+M21+N21*5+O21*5+P21+Q21 -> 1580 | X21: =C21*$C$3+D21*$D$3+E21*$E$3+F21*$F$3+G21*$G$3+H21*$H$3+I21*$I$3+J21*$J$3+K21*$K$3+L21*$L$3+M21*$M$3+N21*$N$3+O21*$O$3+P21*$P$3 -> 121269.5 | Y21: =B21*99+C21*$C$3+D21*$D$3+E21*$E$3+F21*$F$3+G21*$G$3+H21*$H$3+I21*$I$3+J21*$J$3+K21*$K$3+L21*$L$3+M21*$M$3+N21*$N$3+O21*$O$3+P21*$P$3 -> 157899.5
A22: 史嘉琳 | B22: 167 | C22: 204 | D22: 965 | E22: 626 | G22: 264 | J22: 4 | R22: 10 | U22: =SUM(C22:P22)-D22 -> 1098 | V22: =SUM(B22:P22)-D22 -> 1265 | W22: =B22+C22+E22+F22+G22*2+H22*3+I22*3+J22+K22*6+L22*5+M22+N22*5+O22*5+P22+Q22 -> 1529 | X22: =C22*$C$3+D22*$D$3+E22*$E$3+F22*$F$3+G22*$G$3+H22*$H$3+I22*$I$3+J22*$J$3+K22*$K$3+L22*$L$3+M22*$M$3+N22*$N$3+O22*$O$3+P22*$P$3 -> 164125.5 | Y22: =B22*99+C22*$C$3+D22*$D$3+E22*$E$3+F22*$F$3+G22*$G$3+H22*$H$3+I22*$I$3+J22*$J$3+K22*$K$3+L22*$L$3+M22*$M$3+N22*$N$3+O22*$O$3+P22*$P$3 -> 180658.5
A23: 孙承飞 | B23: 252 | C23: 1 | D23: 472 | E23: 514 | F23: 2 | G23: 29 | J23: 15 | K23: 15 | L23: 2 | R23: 6 | S23: 2 | U23: =SUM(C23:P23)-D23 -> 578 | V23: =SUM(B23:P23)-D23 -> 830 | W23: =B23+C23+E23+F23+G23*2+H23*3+I23*3+J23+K23*6+L23*5+M23+N23*5+O23*5+P23+Q23 -> 942 | X23: =C23*$C$3+D23*$D$3+E23*$E$3+F23*$F$3+G23*$G$3+H23*$H$3+I23*$I$3+J23*$J$3+K23*$K$3+L23*$L$3+M23*$M$3+N23*$N$3+O23*$O$3+P23*$P$3 -> 64251 | Y23: =B23*99+C23*$C$3+D23*$D$3+E23*$E$3+F23*$F$3+G23*$G$3+H23*$H$3+I23*$I$3+J23*$J$3+K23*$K$3+L23*$L$3+M23*$M$3+N23*$N$3+O23*$O$3+P23*$P$3 -> 89199
A24: 赵希平 | B24: 261 | C24: 4 | D24: 421 | E24: 428 | G24: 48 | J24: 14 | K24: 24 | L24: 3 | R24: 6 | S24: 2 | U24: =SUM(C24:P24)-D24 -> 521 | V24: =SUM(B24:P24)-D24 -> 782 | W24: =B24+C24+E24+F24+G24*2+H24*3+I24*3+J24+K24*6+L24*5+M24+N24*5+O24*5+P24+Q24 -> 962 | X24: =C24*$C$3+D24*$D$3+E24*$E$3+F24*$F$3+G24*$G$3+H24*$H$3+I24*$I$3+J24*$J$3+K24*$K$3+L24*$L$3+M24*$M$3+N24*$N$3+O24*$O$3+P24*$P$3 -> 61924.5 | Y24: =B24*99+C24*$C$3+D24*$D$3+E24*$E$3+F24*$F$3+G24*$G$3+H24*$H$3+I24*$I$3+J24*$J$3+K24*$K$3+L24*$L$3+M24*$M$3+N24*$N$3+O24*$O$3+P24*$P$3 -> 87763.5
U25: =SUM(C25:P25)-D25 -> 0 | V25: =SUM(B25:P25)-D25 -> 0 | W25: =B25+C25+E25+F25+G25*2+H25*3+I25*3+J25+K25*6+L25*5+M25+N25*5+O25*5+P25+Q25 -> 0 | X25: =C25*$C$3+D25*$D$3+E25*$E$3+F25*$F$3+G25*$G$3+H25*$H$3+I25*$I$3+J25*$J$3+K25*$K$3+L25*$L$3+M25*$M$3+N25*$N$3+O25*$O$3+P25*$P$3 -> 0 | Y25: =B25*99+C25*$C$3+D25*$D$3+E25*$E$3+F25*$F$3+G25*$G$3+H25*$H$3+I25*$I$3+J25*$J$3+K25*$K$3+L25*$L$3+M25*$M$3+N25*$N$3+O25*$O$3+P25*$P$3 -> 0
U26: =SUM(C26:P26)-D26 -> 0 | V26: =SUM(B26:P26)-D26 -> 0 | W26: =B26+C26+E26+F26+G26*2+H26*3+I26*3+J26+K26*6+L26*5+M26+N26*5+O26*5+P26+Q26 -> 0 | X26: =C26*$C$3+D26*$D$3+E26*$E$3+F26*$F$3+G26*$G$3+H26*$H$3+I26*$I$3+J26*$J$3+K26*$K$3+L26*$L$3+M26*$M$3+N26*$N$3+O26*$O$3+P26*$P$3 -> 0 | Y26: =B26*99+C26*$C$3+D26*$D$3+E26*$E$3+F26*$F$3+G26*$G$3+H26*$H$3+I26*$I$3+J26*$J$3+K26*$K$3+L26*$L$3+M26*$M$3+N26*$N$3+O26*$O$3+P26*$P$3 -> 0
A27: 李楠 | U27: =SUM(C27:P27)-D27 -> 0 | V27: =SUM(B27:P27)-D27 -> 0 | W27: =B27+C27+E27+F27+G27*2+H27*3+I27*3+J27+K27*6+L27*5+M27+N27*5+O27*5+P27+Q27 -> 0 | X27: =C27*$C$3+D27*$D$3+E27*$E$3+F27*$F$3+G27*$G$3+H27*$H$3+I27*$I$3+J27*$J$3+K27*$K$3+L27*$L$3+M27*$M$3+N27*$N$3+O27*$O$3+P27*$P$3 -> 0 | Y27: =B27*99+C27*$C$3+D27*$D$3+E27*$E$3+F27*$F$3+G27*$G$3+H27*$H$3+I27*$I$3+J27*$J$3+K27*$K$3+L27*$L$3+M27*$M$3+N27*$N$3+O27*$O$3+P27*$P$3 -> 0
A28: 韩天福 | U28: =SUM(C28:P28)-D28 -> 0 | V28: =SUM(B28:P28)-D28 -> 0 | W28: =B28+C28+E28+F28+G28*2+H28*3+I28*3+J28+K28*6+L28*5+M28+N28*5+O28*5+P28+Q28 -> 0 | X28: =C28*$C$3+D28*$D$3+E28*$E$3+F28*$F$3+G28*$G$3+H28*$H$3+I28*$I$3+J28*$J$3+K28*$K$3+L28*$L$3+M28*$M$3+N28*$N$3+O28*$O$3+P28*$P$3 -> 0 | Y28: =B28*99+C28*$C$3+D28*$D$3+E28*$E$3+F28*$F$3+G28*$G$3+H28*$H$3+I28*$I$3+J28*$J$3+K28*$K$3+L28*$L$3+M28*$M$3+N28*$N$3+O28*$O$3+P28*$P$3 -> 0
A29: 刘海燕 | B29: 81 | C29: 72 | D29: 703 | E29: 603 | F29: 7 | G29: 192 | U29: =SUM(C29:P29)-D29 -> 874 | V29: =SUM(B29:P29)-D29 -> 955 | W29: 0 | X29: =C29*$C$3+D29*$D$3+E29*$E$3+F29*$F$3+G29*$G$3+H29*$H$3+I29*$I$3+J29*$J$3+K29*$K$3+L29*$L$3+M29*$M$3+N29*$N$3+O29*$O$3+P29*$P$3 -> 124140.5 | Y29: =B29*99+C29*$C$3+D29*$D$3+E29*$E$3+F29*$F$3+G29*$G$3+H29*$H$3+I29*$I$3+J29*$J$3+K29*$K$3+L29*$L$3+M29*$M$3+N29*$N$3+O29*$O$3+P29*$P$3 -> 132159.5
U30: =SUM(B30:Q30) -> 0 | V30: =SUM(B30:P30)-D30 -> 0 | W30: =B30+C30+E30+F30+G30*2+H30*3+I30*3+J30+K30*6+L30*5+M30+N30*5+O30*5+P30+Q30 -> 0 | X30: =C30*$C$3+D30*$D$3+E30*$E$3+F30*$F$3+G30*$G$3+H30*$H$3+I30*$I$3+J30*$J$3+K30*$K$3+L30*$L$3+M30*$M$3+N30*$N$3+O30*$O$3+P30*$P$3 -> 0 | Y30: =B30*99+C30*$C$3+D30*$D$3+E30*$E$3+F30*$F$3+G30*$G$3+H30*$H$3+I30*$I$3+J30*$J$3+K30*$K$3+L30*$L$3+M30*$M$3+N30*$N$3+O30*$O$3+P30*$P$3 -> 0
